Workbook

Sheet 00_투자판단
C2: 그날의 류 투자 검토 요약
C4: 선택 시나리오 | F4: ='01_가정'!H4 -> 보수
C5: 현재 판단은 조건부 검증 투자입니다. 본 제품의 생리주기 개선 효과, 양산 견적, 실매출은 아직 입증되지 않았습니다. 100일 검증 결과에 따라 후속 집행을 결정합니다.
C8: 주요 결과 | D8: 단위 | F8: 1년차 | G8: 2년차 | H8: 3년차
C9: 본체 출고 | D9: 개 | F9: ='03_월별손익'!F19 -> 56 | G9: ='03_월별손익'!G19 -> 804 | H9: ='03_월별손익'!H19 -> 1680
C10: 총 순매출 | D10: 원 | F10: ='03_월별손익'!F33 -> 5612169.8 | G10: ='03_월별손익'!G33 -> 85304202 | H10: ='03_월별손익'!H33 -> 1.8472419e+08
C11: 리필 순매출 | D11: 원 | F11: ='03_월별손익'!F32 -> 29988 | G11: ='03_월별손익'!G32 -> 2331401.6 | H11: ='03_월별손익'!H32 -> 7407828.8
C12: 광고 후 공헌이익 | D12: 원 | F12: ='03_월별손익'!F48 -> -2364339.8 | G12: ='03_월별손익'!G48 -> -15451930 | H12: ='03_월별손익'!H48 -> -3555650.7
C13: 경제적 인건비 | D13: 원 | F13: ='03_월별손익'!F49 -> 162000000 | G13: ='03_월별손익'!G49 -> 169200000 | H13: ='03_월별손익'!H49 -> 180000000
C14: EBITDA | D14: 원 | F14: ='03_월별손익'!F52 -> -2.4336434e+08 | G14: ='03_월별손익'!G52 -> -2.3265193e+08 | H14: ='03_월별손익'!H52 -> -2.3755565e+08
C15: 영업이익 | D15: 원 | F15: ='03_월별손익'!F54 -> -2.4683656e+08 | G15: ='03_월별손익'!G54 -> -2.4098526e+08 | H15: ='03_월별손익'!H54 -> -2.4588898e+08
C16: 기말 현금 | D16: 원 | F16: ='04_재고현금'!F43 -> -8513773.8 | G16: ='04_재고현금'!G43 -> -2.5232793e+08 | H16: ='04_재고현금'!H43 -> -4.7188363e+08
C17: 연중 최대 추가자금 필요 | D17: 원 | F17: ='04_재고현금'!F44 -> 38513774 | G17: ='04_재고현금'!G44 -> 2.8232793e+08 | H17: ='04_재고현금'!H44 -> 5.0188363e+08
C20: 출시 첫해 본체 유료 CAC | D20: 원 | F20: ='02_단위경제'!F19 -> 80000
C21: 출시 첫해 본체 CM2 | D21: 원 | F21: ='02_단위경제'!F20 -> -62007.682
C22: CM2 목표 달성 허용 CAC | D22: 원 | F22: ='02_단위경제'!F23 -> -2007.6818
C23: 36개월 최대 추가자금 필요 | D23: 원 | F23: =MAX('04_재고현금'!J44:AS44) -> 5.0188363e+08
C24: 36개월 최저 현금 | D24: 원 | F24: =MIN('04_재고현금'!J43:AS43) -> -4.7188363e+08
C25: 첫 현금 부족 월 | D25: 월 | F25: =IF(MIN('04_재고현금'!J43:AS43)>=0,"없음",MATCH(1,J52:AS52,0)) -> 12
C28: 첫 화면의 손익은 독립 사업 기준입니다. 회사 인건비 지원은 현금에만 반영합니다. 기본 시나리오에는 확정되지 않은 올리브영 및 기타 리테일 매출이 포함되지 않습니다.
C31: 투자 결정을 바꾸는 세 가지 증거
C33: 고객 가격 제시 후 실제 지불과 재사용이 발생하는가. 예약금은 관심 신호이며 실제 출고와 환불을 확인하기 전 판매 전환율로 사용하지 않습니다.
C35: 제품 발목 착용과 지압이 기존 온열 또는 간단한 밴드보다 고객에게 추가 가치를 주는가. 온열 압박의 안전 범위를 먼저 정합니다.
C37: 경제성 검수 원가와 물류 AS 및 광고를 뺀 본체 이익이 양수인가. 리필 구매를 0으로 바꿔도 사업이 버틸 수 있는지 확인합니다.
C40: 사용 순서 01 가정에서 시나리오 선택과 노란 입력 수정 → 00 요약 확인 → 02 단위경제와 04 재고현금 확인. 실제 데이터는 08 실측입력에 기록합니다.
J44: 연도 | K44: 순매출 백만원 | L44: 영업이익 백만원 | M44: 기말현금 백만원
J45: 1년차 | K45: =F10/1000000 -> 5.6121698 | L45: =F15/1000000 -> -246.83656 | M45: =F16/1000000 -> -8.5137738
J46: 2년차 | K46: =G10/1000000 -> 85.304202 | L46: =G15/1000000 -> -240.98526 | M46: =G16/1000000 -> -252.32793
J47: 3년차 | K47: =H10/1000000 -> 184.72419 | L47: =H15/1000000 -> -245.88898 | M47: =H16/1000000 -> -471.88363
J51: 1 | K51: 2 | L51: 3 | M51: 4 | N51: 5 | O51: 6 | P51: 7 | Q51: 8 | R51: 9 | S51: 10 | T51: 11 | U51: 12 | V51: 13 | W51: 14 | X51: 15 | Y51: 16 | Z51: 17 | AA51: 18 | AB51: 19 | AC51: 20 | AD51: 21 | AE51: 22 | AF51: 23 | AG51: 24 | AH51: 25 | AI51: 26 | AJ51: 27 | AK51: 28 | AL51: 29 | AM51: 30 | AN51: 31 | AO51: 32 | AP51: 33 | AQ51: 34 | AR51: 35 | AS51: 36
J52: =IF('04_재고현금'!J43<0,1,0) -> 0 | K52: =IF('04_재고현금'!K43<0,1,0) -> 0 | L52: =IF('04_재고현금'!L43<0,1,0) -> 0 | M52: =IF('04_재고현금'!M43<0,1,0) -> 0 | N52: =IF('04_재고현금'!N43<0,1,0) -> 0 | O52: =IF('04_재고현금'!O43<0,1,0) -> 0 | P52: =IF('04_재고현금'!P43<0,1,0) -> 0 | Q52: =IF('04_재고현금'!Q43<0,1,0) -> 0 | ... AS52: =IF('04_재고현금'!AS43<0,1,0) -> 1

Sheet 01_가정
C2: 사업 가정 · 숫자를 바꾸면 매출과 현금이 달라지는 설정표
F4: 1 | G4: 선택 결과 | H4: =CHOOSE(F4,"보수","기준","확장") -> 보수
C5: 모델 시작월 | F5: 46388
C6: ① F4에서 1 보수 / 2 기준 / 3 확장 선택 → ② 노란 칸의 가정 수정 → ③ 00_투자판단에서 결과 확인. 파란 숫자는 입력, 적용 행은 자동 계산입니다. 1~3년차는 시작월부터 12개월씩이며 출시 후 경과연도가 아닙니다. 확정 실적·견적이 없는 숫자는 기존 시험값을 유지했습니다.
C8: 가정 항목 | D8: 구분 | E8: 단위 | F8: 1년차 | G8: 2년차 | H8: 3년차 | J8: 뜻 · 기존 숫자의 근거 · 수정 기준
C10: 본체 실결제가 | D10: 적용 | E10: 원 | F10: =IF(CHOOSE($F$4,COUNT(F11),COUNT(F12),COUNT(F13))=0,"미입력",CHOOSE($F$4,F11,F12,F13)) -> 129000 | G10: =IF(CHOOSE($F$4,COUNT(G11),COUNT(G12),COUNT(G13))=0,"미입력",CHOOSE($F$4,G11,G12,G13)) -> 129000 | H10: =IF(CHOOSE($F$4,COUNT(H11),COUNT(H12),COUNT(H13))=0,"미입력",CHOOSE($F$4,H11,H12,H13)) -> 129000 | J10: 고객이 본체 키트 1개에 실제 결제하는 금액(VAT 포함). 기준 149,000원은 종전 모델 S05의 시험값이며 가격조사 결과가 아닙니다. 보수는 할인 판매, 확장은 높은 가격 수용을 가정합니다. 실제 할인 후 판매가로 교체하세요. A01
D11: 보수 | F11: 129000 | G11: 129000 | H11: 129000
D12: 기준 | F12: 149000 | G12: 149000 | H12: 149000
D13: 확장 | F13: 169000 | G13: 169000 | H13: 169000
C14: 완제품 키트 제조원가 | D14: 적용 | E14: 원 | F14: =IF(CHOOSE($F$4,COUNT(F15),COUNT(F16),COUNT(F17))=0,"미입력",CHOOSE($F$4,F15,F16,F17)) -> 70000 | G14: =IF(CHOOSE($F$4,COUNT(G15),COUNT(G16),COUNT(G17))=0,"미입력",CHOOSE($F$4,G15,G16,G17)) -> 65000 | H14: =IF(CHOOSE($F$4,COUNT(H15),COUNT(H16),COUNT(H17))=0,"미입력",CHOOSE($F$4,H15,H16,H17)) -> 60000 | J14: 본체 1개+동봉 패치 12개의 제조·포장 원가(VAT 제외). 55,000→50,000→46,000원은 양산 효율 개선을 미리 넣은 가정이며 견적이 없습니다. 원가 하락이 확인되지 않으면 2·3년차도 같은 금액으로 두세요. A02
D15: 보수 | F15: 70000 | G15: 65000 | H15: 60000
D16: 기준 | F16: 55000 | G16: 50000 | H16: 46000
D17: 확장 | F17: 45000 | G17: 40000 | H17: 37000
C18: 유료 유입 클릭당 비용 | D18: 적용 | E18: 원 | F18: =IF(CHOOSE($F$4,COUNT(F19),COUNT(F20),COUNT(F21))=0,"미입력",CHOOSE($F$4,F19,F20,F21)) -> 1200 | G18: =IF(CHOOSE($F$4,COUNT(G19),COUNT(G20),COUNT(G21))=0,"미입력",CHOOSE($F$4,G19,G20,G21)) -> 1100 | H18: =IF(CHOOSE($F$4,COUNT(H19),COUNT(H20),COUNT(H21))=0,"미입력",CHOOSE($F$4,H19,H20,H21)) -> 1000 | J18: 광고로 방문 1회를 얻는 비용(CPC). 기준 900원은 광고 실적이 없는 시험값입니다. 광고비÷유효 클릭수로 확인하세요. 800원·750원으로 내려가는 것은 광고 효율이 개선된다는 추가 가정입니다. A03
D19: 보수 | F19: 1200 | G19: 1100 | H19: 1000
D20: 기준 | F20: 900 | G20: 800 | H20: 750
D21: 확장 | F21: 700 | G21: 650 | H21: 600
C22: 유효 클릭의 출고 전환율 | D22: 적용 | E22: % | F22: =IF(CHOOSE($F$4,COUNT(F23),COUNT(F24),COUNT(F25))=0,"미입력",CHOOSE($F$4,F23,F24,F25)) -> 0.015 | G22: =IF(CHOOSE($F$4,COUNT(G23),COUNT(G24),COUNT(G25))=0,"미입력",CHOOSE($F$4,G23,G24,G25)) -> 0.018 | H22: =IF(CHOOSE($F$4,COUNT(H23),COUNT(H24),COUNT(H25))=0,"미입력",CHOOSE($F$4,H23,H24,H25)) -> 0.02 | J22: 방문 중 결제 후 실제 출고까지 이어지는 비율. 2.5%는 방문 1,000회당 출고 25건을 뜻합니다. 예약자 비율이 아닙니다. 현재 자연 유입에도 같은 비율을 적용합니다. 3.0%·3.5% 개선은 미검증입니다. A04
D23: 보수 | F23: 0.015 | G23: 0.018 | H23: 0.02
D24: 기준 | F24: 0.025 | G24: 0.03 | H24: 0.035
D25: 확장 | F25: 0.04 | G25: 0.045 | H25: 0.05
C26: 본체 DTC 전액 환불률 | D26: 적용 | E26: % | F26: =IF(CHOOSE($F$4,COUNT(F27),COUNT(F28),COUNT(F29))=0,"미입력",CHOOSE($F$4,F27,F28,F29)) -> 0.15 | G26: =IF(CHOOSE($F$4,COUNT(G27),COUNT(G28),COUNT(G29))=0,"미입력",CHOOSE($F$4,G27,G28,G29)) -> 0.12 | H26: =IF(CHOOSE($F$4,COUNT(H27),COUNT(H28),COUNT(H29))=0,"미입력",CHOOSE($F$4,H27,H28,H29)) -> 0.1 | J26: 출고한 본체 중 전액 환불되는 비율. 8%이면 100대 출고 중 8대 환불을 예상합니다. 환불된 제품의 제조원가·배송비도 이미 발생한 비용이며 회수품 재판매 수입은 0으로 둡니다. 동일 출고집단의 실적으로 교체하세요. A05
D27: 보수 | F27: 0.15 | G27: 0.12 | H27: 0.1
D28: 기준 | F28: 0.08 | G28: 0.07 | H28: 0.06
D29: 확장 | F29: 0.05 | G29: 0.04 | H29: 0.03
C30: 첫 리필 유료 참여율 | D30: 적용 | E30: % | F30: =IF(CHOOSE($F$4,COUNT(F31),COUNT(F32),COUNT(F33))=0,"미입력",CHOOSE($F$4,F31,F32,F33)) -> 0.1 | G30: =IF(CHOOSE($F$4,COUNT(G31),COUNT(G32),COUNT(G33))=0,"미입력",CHOOSE($F$4,G31,G32,G33)) -> 0.12 | H30: =IF(CHOOSE($F$4,COUNT(H31),COUNT(H32),COUNT(H33))=0,"미입력",CHOOSE($F$4,H31,H32,H33)) -> 0.15 | J30: 환불하지 않은 본체 고객 중 다음 달 처음 리필을 유료 구매하는 비율. 25%는 고객 100명 중 25명입니다. 구독 계약이나 확정 매출이 아닙니다. 구매 후 한 달을 지난 고객의 첫 리필 구매율로 확인하세요. A06
D31: 보수 | F31: 0.1 | G31: 0.12 | H31: 0.15
D32: 기준 | F32: 0.25 | G32: 0.3 | H32: 0.35
D33: 확장 | F33: 0.4 | G33: 0.45 | H33: 0.5
C34: 리필 구매자 월 유지율 | D34: 적용 | E34: % | F34: =IF(CHOOSE($F$4,COUNT(F35),COUNT(F36),COUNT(F37))=0,"미입력",CHOOSE($F$4,F35,F36,F37)) -> 0.75 | G34: =IF(CHOOSE($F$4,COUNT(G35),COUNT(G36),COUNT(G37))=0,"미입력",CHOOSE($F$4,G35,G36,G37)) -> 0.78 | H34: =IF(CHOOSE($F$4,COUNT(H35),COUNT(H36),COUNT(H37))=0,"미입력",CHOOSE($F$4,H35,H36,H37)) -> 0.8 | J34: 지난달 리필을 산 사람이 이번 달에도 사는 비율. 90%이면 100명→90명→81명으로 줄어듭니다. 모든 본체 고객의 90%가 매달 산다는 뜻이 아닙니다. 구매 간격이 한 달보다 길면 이 모델의 월 반복구매 가정을 재검토하세요. A07
D35: 보수 | F35: 0.75 | G35: 0.78 | H35: 0.8
D36: 기준 | F36: 0.9 | G36: 0.91 | H36: 0.92
D37: 확장 | F37: 0.94 | G37: 0.95 | H37: 0.96
C38: 성숙 월 자연 유입 | D38: 적용 | E38: 명 | F38: =IF(CHOOSE($F$4,COUNT(F39),COUNT(F40),COUNT(F41))=0,"미입력",CHOOSE($F$4,F39,F40,F41)) -> 500 | G38: =IF(CHOOSE($F$4,COUNT(G39),COUNT(G40),COUNT(G41))=0,"미입력",CHOOSE($F$4,G39,G40,G41)) -> 1000 | H38: =IF(CHOOSE($F$4,COUNT(H39),COUNT(H40),COUNT(H41))=0,"미입력",CHOOSE($F$4,H39,H40,H41)) -> 2000 | J38: 광고 외 검색·콘텐츠·추천으로 오는 월 방문 수. 기준 1,000→3,000→5,000회는 유입 확대 계획이며 관측값이 아닙니다. 출시 첫 달 50%, 둘째 달 75%만 적용합니다. 콘텐츠 인건비·운영비는 별도 지출입니다. A08
D39: 보수 | F39: 500 | G39: 1000 | H39: 2000
D40: 기준 | F40: 1000 | G40: 3000 | H40: 5000
D41: 확장 | F41: 1500 | G41: 5000 | H41: 10000
C42: 성숙 월 광고비 | D42: 적용 | E42: 원 | F42: =IF(CHOOSE($F$4,COUNT(F43),COUNT(F44),COUNT(F45))=0,"미입력",CHOOSE($F$4,F43,F44,F45)) -> 1500000 | G42: =IF(CHOOSE($F$4,COUNT(G43),COUNT(G44),COUNT(G45))=0,"미입력",CHOOSE($F$4,G43,G44,G45)) -> 3000000 | H42: =IF(CHOOSE($F$4,COUNT(H43),COUNT(H44),COUNT(H45))=0,"미입력",CHOOSE($F$4,H43,H44,H45)) -> 5000000 | J42: 판매가 안정된 달에 쓸 광고비. 기준 월 200만→600만→1,200만원은 예산 확대 계획입니다. 첫 출시월 50%, 다음 달 75%, 이후 100% 집행. 광고비÷CPC×전환율로 유료 출고를 계산하므로 판매량을 보장하지 않습니다. A09
D43: 보수 | F43: 1500000 | G43: 3000000 | H43: 5000000
D44: 기준 | F44: 2000000 | G44: 6000000 | H44: 12000000
...

Sheet 02_단위경제
C2: 본체와 리필에서 실제로 남는 금액
C4: 선택 시나리오 | F4: ='01_가정'!H4 -> 보수
C6: 지표 | D6: 단위 | F6: 1년차 | G6: 2년차 | H6: 3년차
C7: DTC 본체 한 대 기준
C8: DTC 실결제가 | D8: 원 | F8: ='01_가정'!F10 -> 129000 | G8: ='01_가정'!G10 -> 129000 | H8: ='01_가정'!H10 -> 129000
C9: 환불 전 VAT 제외 매출 | D9: 원 | F9: =F8/(1+'01_가정'!$F$85) -> 117272.73 | G9: =G8/(1+'01_가정'!$F$85) -> 117272.73 | H9: =H8/(1+'01_가정'!$F$85) -> 117272.73
C10: 비환불 비율 | D10: % | F10: =1-'01_가정'!F26 -> 0.85 | G10: =1-'01_가정'!G26 -> 0.88 | H10: =1-'01_가정'!H26 -> 0.9
C11: 출고당 순매출 | D11: 원 | F11: =F9*F10 -> 99681.818 | G11: =G9*G10 -> 103200 | H11: =H9*H10 -> 105545.45
C12: 완제품 키트 원가 | D12: 원 | F12: ='01_가정'!F14 -> 70000 | G12: ='01_가정'!G14 -> 65000 | H12: ='01_가정'!H14 -> 60000
C13: 결제 수수료 | D13: 원 | F13: =F11*'01_가정'!$F$86 -> 3289.5 | G13: =G11*'01_가정'!$F$86 -> 3405.6 | H13: =H11*'01_가정'!$F$86 -> 3483
C14: 출고 물류비 | D14: 원 | F14: ='01_가정'!$F$87 -> 4500 | G14: ='01_가정'!$F$87 -> 4500 | H14: ='01_가정'!$F$87 -> 4500
C15: 기대 반품 처리비 | D15: 원 | F15: =(1-F10)*'01_가정'!$F$88 -> 900 | G15: =(1-G10)*'01_가정'!$F$88 -> 720 | H15: =(1-H10)*'01_가정'!$F$88 -> 600
C16: AS 기대비용 | D16: 원 | F16: ='01_가정'!$F$89 -> 2000 | G16: ='01_가정'!$F$89 -> 2000 | H16: ='01_가정'!$F$89 -> 2000
C17: 변동 상담비 | D17: 원 | F17: ='01_가정'!$F$90 -> 1000 | G17: ='01_가정'!$F$90 -> 1000 | H17: ='01_가정'!$F$90 -> 1000
C18: 광고 전 공헌이익 CM1 | D18: 원 | F18: =F11-SUM(F12:F17) -> 17992.318 | G18: =G11-SUM(G12:G17) -> 26574.4 | H18: =H11-SUM(H12:H17) -> 33962.455
C19: 유료 신규 출고 CAC | D19: 원 | F19: =IF('01_가정'!F22>0,'01_가정'!F18/'01_가정'!F22,"n.a.") -> 80000 | G19: =IF('01_가정'!G22>0,'01_가정'!G18/'01_가정'!G22,"n.a.") -> 61111.111 | H19: =IF('01_가정'!H22>0,'01_가정'!H18/'01_가정'!H22,"n.a.") -> 50000
C20: 광고 후 공헌이익 CM2 | D20: 원 | F20: =IF(ISNUMBER(F19),F18-F19,"n.a.") -> -62007.682 | G20: =IF(ISNUMBER(G19),G18-G19,"n.a.") -> -34536.711 | H20: =IF(ISNUMBER(H19),H18-H19,"n.a.") -> -16037.545
C21: CM2 순매출 비율 | D21: % | F21: =IF(AND(ISNUMBER(F20),F11>0),F20/F11,"n.a.") -> -0.62205609 | G21: =IF(AND(ISNUMBER(G20),G11>0),G20/G11,"n.a.") -> -0.33465805 | H21: =IF(AND(ISNUMBER(H20),H11>0),H20/H11,"n.a.") -> -0.15194918
C22: CM2 관리 목표 | D22: 원 | F22: ='01_가정'!$F$115 -> 20000 | G22: ='01_가정'!$F$115 -> 20000 | H22: ='01_가정'!$F$115 -> 20000
C23: 허용 가능한 CAC | D23: 원 | F23: =F18-F22 -> -2007.6818 | G23: =G18-G22 -> 6574.4 | H23: =H18-H22 -> 13962.455
C24: 목표 CM2에 필요한 전환율 | D24: % | F24: =IF(F23>0,'01_가정'!F18/F23,"n.a.") -> n.a. | G24: =IF(G23>0,'01_가정'!G18/G23,"n.a.") -> 0.16731565 | H24: =IF(H23>0,'01_가정'!H18/H23,"n.a.") -> 0.071620645
C25: 월 고정 인건비와 운영비 | D25: 원 | F25: ='01_가정'!F58*'01_가정'!F62+'01_가정'!F66 -> 15500000 | G25: ='01_가정'!G58*'01_가정'!G62+'01_가정'!G66 -> 16600000 | H25: ='01_가정'!H58*'01_가정'!H62+'01_가정'!H66 -> 18000000
C26: 인건비·운영비 회수 출고량 | D26: 개 | F26: =IF(AND(ISNUMBER(F20),F20>0),ROUNDUP(F25/F20,0),"n.a.") -> n.a. | G26: =IF(AND(ISNUMBER(G20),G20>0),ROUNDUP(G25/G20,0),"n.a.") -> n.a. | H26: =IF(AND(ISNUMBER(H20),H20>0),ROUNDUP(H25/H20,0),"n.a.") -> n.a.
C29: 납품 채널은 공급가로 매출 인식
C30: 리테일 VAT 제외 공급가 | D30: 원 | F30: ='01_가정'!F10/(1+'01_가정'!$F$85)*'01_가정'!F54 -> 64500 | G30: ='01_가정'!G10/(1+'01_가정'!$F$85)*'01_가정'!G54 -> 64500 | H30: ='01_가정'!H10/(1+'01_가정'!$F$85)*'01_가정'!H54 -> 64500
C31: 리테일 비반품 비율 | D31: % | F31: =1-'01_가정'!$F$98 -> 0.97 | G31: =1-'01_가정'!$F$98 -> 0.97 | H31: =1-'01_가정'!$F$98 -> 0.97
C32: 리테일 출고당 순매출 | D32: 원 | F32: =F30*F31 -> 62565 | G32: =G30*G31 -> 62565 | H32: =H30*H31 -> 62565
C33: 리테일 제품 원가 | D33: 원 | F33: ='01_가정'!F14 -> 70000 | G33: ='01_가정'!G14 -> 65000 | H33: ='01_가정'!H14 -> 60000
C34: 리테일 물류비 | D34: 원 | F34: ='01_가정'!$F$97 -> 2000 | G34: ='01_가정'!$F$97 -> 2000 | H34: ='01_가정'!$F$97 -> 2000
C35: 리테일 기대 반품 처리비 | D35: 원 | F35: =(1-F31)*'01_가정'!$F$88 -> 180 | G35: =(1-G31)*'01_가정'!$F$88 -> 180 | H35: =(1-H31)*'01_가정'!$F$88 -> 180
C36: 리테일 AS 기대비용 | D36: 원 | F36: ='01_가정'!$F$89 -> 2000 | G36: ='01_가정'!$F$89 -> 2000 | H36: ='01_가정'!$F$89 -> 2000
C37: 리테일 상담비 | D37: 원 | F37: ='01_가정'!$F$90 -> 1000 | G37: ='01_가정'!$F$90 -> 1000 | H37: ='01_가정'!$F$90 -> 1000
C38: 리테일 출고당 공헌이익 | D38: 원 | F38: =F32-SUM(F33:F37) -> -12615 | G38: =G32-SUM(G33:G37) -> -7615 | H38: =H32-SUM(H33:H37) -> -2615
C42: 리필은 실제 유료 재구매만 반영
C43: 리필 24개팩 실결제가 | D43: 원 | F43: ='01_가정'!F70 -> 9900 | G43: ='01_가정'!G70 -> 9900 | H43: ='01_가정'!H70 -> 9900
C44: 리필 주문당 순매출 | D44: 원 | F44: =F43/(1+'01_가정'!$F$85)*(1-'01_가정'!$F$93) -> 8820 | G44: =G43/(1+'01_가정'!$F$85)*(1-'01_가정'!$F$93) -> 8820 | H44: =H43/(1+'01_가정'!$F$85)*(1-'01_가정'!$F$93) -> 8820
C45: 리필 제품 원가 | D45: 원 | F45: ='01_가정'!F74 -> 4500 | G45: ='01_가정'!G74 -> 4300 | H45: ='01_가정'!H74 -> 4000
C46: 리필 결제 수수료 | D46: 원 | F46: =F44*'01_가정'!$F$92 -> 291.06 | G46: =G44*'01_가정'!$F$92 -> 291.06 | H46: =H44*'01_가정'!$F$92 -> 291.06
C47: 리필 출고 물류비 | D47: 원 | F47: ='01_가정'!$F$91 -> 3000 | G47: ='01_가정'!$F$91 -> 3000 | H47: ='01_가정'!$F$91 -> 3000
C48: 리필 반품 처리 기대비용 | D48: 원 | F48: ='01_가정'!$F$93*'01_가정'!$F$88 -> 120 | G48: ='01_가정'!$F$93*'01_가정'!$F$88 -> 120 | H48: ='01_가정'!$F$93*'01_가정'!$F$88 -> 120
...

Sheet 03_월별손익
C2: 고객 유입에서 계산한 36개월 손익
C4: 선택 시나리오 | F4: ='01_가정'!H4 -> 보수
F5: 1년차 | G5: 2년차 | H5: 3년차 | J5: =EDATE('01_가정'!$F$5,0) -> 46388 | K5: =EDATE('01_가정'!$F$5,1) -> 46419 | L5: =EDATE('01_가정'!$F$5,2) -> 46447 | M5: =EDATE('01_가정'!$F$5,3) -> 46478 | N5: =EDATE('01_가정'!$F$5,4) -> 46508 | O5: =EDATE('01_가정'!$F$5,5) -> 46539 | P5: =EDATE('01_가정'!$F$5,6) -> 46569 | Q5: =EDATE('01_가정'!$F$5,7) -> 46600 | R5: =EDATE('01_가정'!$F$5,8) -> 46631 | S5: =EDATE('01_가정'!$F$5,9) -> 46661 | T5: =EDATE('01_가정'!$F$5,10) -> 46692 | U5: =EDATE('01_가정'!$F$5,11) -> 46722 | V5: =EDATE('01_가정'!$F$5,12) -> 46753 | W5: =EDATE('01_가정'!$F$5,13) -> 46784 | X5: =EDATE('01_가정'!$F$5,14) -> 46813 | Y5: =EDATE('01_가정'!$F$5,15) -> 46844 | Z5: =EDATE('01_가정'!$F$5,16) -> 46874 | AA5: =EDATE('01_가정'!$F$5,17) -> 46905 | AB5: =EDATE('01_가정'!$F$5,18) -> 46935 | AC5: =EDATE('01_가정'!$F$5,19) -> 46966 | AD5: =EDATE('01_가정'!$F$5,20) -> 46997 | AE5: =EDATE('01_가정'!$F$5,21) -> 47027 | AF5: =EDATE('01_가정'!$F$5,22) -> 47058 | AG5: =EDATE('01_가정'!$F$5,23) -> 47088 | AH5: =EDATE('01_가정'!$F$5,24) -> 47119 | AI5: =EDATE('01_가정'!$F$5,25) -> 47150 | AJ5: =EDATE('01_가정'!$F$5,26) -> 47178 | AK5: =EDATE('01_가정'!$F$5,27) -> 47209 | AL5: =EDATE('01_가정'!$F$5,28) -> 47239 | AM5: =EDATE('01_가정'!$F$5,29) -> 47270 | AN5: =EDATE('01_가정'!$F$5,30) -> 47300 | AO5: =EDATE('01_가정'!$F$5,31) -> 47331 | AP5: =EDATE('01_가정'!$F$5,32) -> 47362 | AQ5: =EDATE('01_가정'!$F$5,33) -> 47392 | AR5: =EDATE('01_가정'!$F$5,34) -> 47423 | AS5: =EDATE('01_가정'!$F$5,35) -> 47453
J6: 1 | K6: 2 | L6: 3 | M6: 4 | N6: 5 | O6: 6 | P6: 7 | Q6: 8 | R6: 9 | S6: 10 | T6: 11 | U6: 12 | V6: 13 | W6: 14 | X6: 15 | Y6: 16 | Z6: 17 | AA6: 18 | AB6: 19 | AC6: 20 | AD6: 21 | AE6: 22 | AF6: 23 | AG6: 24 | AH6: 25 | AI6: 26 | AJ6: 27 | AK6: 28 | AL6: 29 | AM6: 30 | AN6: 31 | AO6: 32 | AP6: 33 | AQ6: 34 | AR6: 35 | AS6: 36
C8: 판매 가능 일정 가정 | D8: 0 또는 1 | J8: =IF(J$6>='01_가정'!F46,1,0) -> 0 | K8: =IF(K$6>='01_가정'!F46,1,0) -> 0 | L8: =IF(L$6>='01_가정'!F46,1,0) -> 0 | M8: =IF(M$6>='01_가정'!F46,1,0) -> 0 | N8: =IF(N$6>='01_가정'!F46,1,0) -> 0 | O8: =IF(O$6>='01_가정'!F46,1,0) -> 0 | P8: =IF(P$6>='01_가정'!F46,1,0) -> 0 | Q8: =IF(Q$6>='01_가정'!F46,1,0) -> 0 | R8: =IF(R$6>='01_가정'!F46,1,0) -> 0 | S8: =IF(S$6>='01_가정'!F46,1,0) -> 1 | T8: =IF(T$6>='01_가정'!F46,1,0) -> 1 | U8: =IF(U$6>='01_가정'!F46,1,0) -> 1 | V8: =IF(V$6>='01_가정'!F46,1,0) -> 1 | W8: =IF(W$6>='01_가정'!F46,1,0) -> 1 | X8: =IF(X$6>='01_가정'!F46,1,0) -> 1 | Y8: =IF(Y$6>='01_가정'!F46,1,0) -> 1 | Z8: =IF(Z$6>='01_가정'!F46,1,0) -> 1 | AA8: =IF(AA$6>='01_가정'!F46,1,0) -> 1 | AB8: =IF(AB$6>='01_가정'!F46,1,0) -> 1 | AC8: =IF(AC$6>='01_가정'!F46,1,0) -> 1 | AD8: =IF(AD$6>='01_가정'!F46,1,0) -> 1 | AE8: =IF(AE$6>='01_가정'!F46,1,0) -> 1 | AF8: =IF(AF$6>='01_가정'!F46,1,0) -> 1 | AG8: =IF(AG$6>='01_가정'!F46,1,0) -> 1 | AH8: =IF(AH$6>='01_가정'!F46,1,0) -> 1 | AI8: =IF(AI$6>='01_가정'!F46,1,0) -> 1 | AJ8: =IF(AJ$6>='01_가정'!F46,1,0) -> 1 | AK8: =IF(AK$6>='01_가정'!F46,1,0) -> 1 | AL8: =IF(AL$6>='01_가정'!F46,1,0) -> 1 | AM8: =IF(AM$6>='01_가정'!F46,1,0) -> 1 | AN8: =IF(AN$6>='01_가정'!F46,1,0) -> 1 | AO8: =IF(AO$6>='01_가정'!F46,1,0) -> 1 | AP8: =IF(AP$6>='01_가정'!F46,1,0) -> 1 | AQ8: =IF(AQ$6>='01_가정'!F46,1,0) -> 1 | AR8: =IF(AR$6>='01_가정'!F46,1,0) -> 1 | AS8: =IF(AS$6>='01_가정'!F46,1,0) -> 1
C9: 출시 초기 집행 비중 | D9: % | J9: =IF(J8=0,0,IF(J$6='01_가정'!F46,0.5,IF(J$6='01_가정'!F46+1,0.75,1))) -> 0 | K9: =IF(K8=0,0,IF(K$6='01_가정'!F46,0.5,IF(K$6='01_가정'!F46+1,0.75,1))) -> 0 | L9: =IF(L8=0,0,IF(L$6='01_가정'!F46,0.5,IF(L$6='01_가정'!F46+1,0.75,1))) -> 0 | M9: =IF(M8=0,0,IF(M$6='01_가정'!F46,0.5,IF(M$6='01_가정'!F46+1,0.75,1))) -> 0 | N9: =IF(N8=0,0,IF(N$6='01_가정'!F46,0.5,IF(N$6='01_가정'!F46+1,0.75,1))) -> 0 | O9: =IF(O8=0,0,IF(O$6='01_가정'!F46,0.5,IF(O$6='01_가정'!F46+1,0.75,1))) -> 0 | P9: =IF(P8=0,0,IF(P$6='01_가정'!F46,0.5,IF(P$6='01_가정'!F46+1,0.75,1))) -> 0 | Q9: =IF(Q8=0,0,IF(Q$6='01_가정'!F46,0.5,IF(Q$6='01_가정'!F46+1,0.75,1))) -> 0 | R9: =IF(R8=0,0,IF(R$6='01_가정'!F46,0.5,IF(R$6='01_가정'!F46+1,0.75,1))) -> 0 | S9: =IF(S8=0,0,IF(S$6='01_가정'!F46,0.5,IF(S$6='01_가정'!F46+1,0.75,1))) -> 0.5 | T9: =IF(T8=0,0,IF(T$6='01_가정'!F46,0.5,IF(T$6='01_가정'!F46+1,0.75,1))) -> 0.75 | U9: =IF(U8=0,0,IF(U$6='01_가정'!F46,0.5,IF(U$6='01_가정'!F46+1,0.75,1))) -> 1 | V9: =IF(V8=0,0,IF(V$6='01_가정'!F46,0.5,IF(V$6='01_가정'!F46+1,0.75,1))) -> 1 | W9: =IF(W8=0,0,IF(W$6='01_가정'!F46,0.5,IF(W$6='01_가정'!F46+1,0.75,1))) -> 1 | X9: =IF(X8=0,0,IF(X$6='01_가정'!F46,0.5,IF(X$6='01_가정'!F46+1,0.75,1))) -> 1 | Y9: =IF(Y8=0,0,IF(Y$6='01_가정'!F46,0.5,IF(Y$6='01_가정'!F46+1,0.75,1))) -> 1 | Z9: =IF(Z8=0,0,IF(Z$6='01_가정'!F46,0.5,IF(Z$6='01_가정'!F46+1,0.75,1))) -> 1 | AA9: =IF(AA8=0,0,IF(AA$6='01_가정'!F46,0.5,IF(AA$6='01_가정'!F46+1,0.75,1))) -> 1 | AB9: =IF(AB8=0,0,IF(AB$6='01_가정'!F46,0.5,IF(AB$6='01_가정'!F46+1,0.75,1))) -> 1 | AC9: =IF(AC8=0,0,IF(AC$6='01_가정'!F46,0.5,IF(AC$6='01_가정'!F46+1,0.75,1))) -> 1 | AD9: =IF(AD8=0,0,IF(AD$6='01_가정'!F46,0.5,IF(AD$6='01_가정'!F46+1,0.75,1))) -> 1 | AE9: =IF(AE8=0,0,IF(AE$6='01_가정'!F46,0.5,IF(AE$6='01_가정'!F46+1,0.75,1))) -> 1 | AF9: =IF(AF8=0,0,IF(AF$6='01_가정'!F46,0.5,IF(AF$6='01_가정'!F46+1,0.75,1))) -> 1 | AG9: =IF(AG8=0,0,IF(AG$6='01_가정'!F46,0.5,IF(AG$6='01_가정'!F46+1,0.75,1))) -> 1 | AH9: =IF(AH8=0,0,IF(AH$6='01_가정'!F46,0.5,IF(AH$6='01_가정'!F46+1,0.75,1))) -> 1 | AI9: =IF(AI8=0,0,IF(AI$6='01_가정'!F46,0.5,IF(AI$6='01_가정'!F46+1,0.75,1))) -> 1 | AJ9: =IF(AJ8=0,0,IF(AJ$6='01_가정'!F46,0.5,IF(AJ$6='01_가정'!F46+1,0.75,1))) -> 1 | AK9: =IF(AK8=0,0,IF(AK$6='01_가정'!F46,0.5,IF(AK$6='01_가정'!F46+1,0.75,1))) -> 1 | AL9: =IF(AL8=0,0,IF(AL$6='01_가정'!F46,0.5,IF(AL$6='01_가정'!F46+1,0.75,1))) -> 1 | AM9: =IF(AM8=0,0,IF(AM$6='01_가정'!F46,0.5,IF(AM$6='01_가정'!F46+1,0.75,1))) -> 1 | AN9: =IF(AN8=0,0,IF(AN$6='01_가정'!F46,0.5,IF(AN$6='01_가정'!F46+1,0.75,1))) -> 1 | AO9: =IF(AO8=0,0,IF(AO$6='01_가정'!F46,0.5,IF(AO$6='01_가정'!F46+1,0.75,1))) -> 1 | AP9: =IF(AP8=0,0,IF(AP$6='01_가정'!F46,0.5,IF(AP$6='01_가정'!F46+1,0.75,1))) -> 1 | AQ9: =IF(AQ8=0,0,IF(AQ$6='01_가정'!F46,0.5,IF(AQ$6='01_가정'!F46+1,0.75,1))) -> 1 | AR9: =IF(AR8=0,0,IF(AR$6='01_가정'!F46,0.5,IF(AR$6='01_가정'!F46+1,0.75,1))) -> 1 | AS9: =IF(AS8=0,0,IF(AS$6='01_가정'!F46,0.5,IF(AS$6='01_가정'!F46+1,0.75,1))) -> 1
C10: 광고비 계획 | D10: 원 | F10: =SUM(J10:U10) -> 3375000 | G10: =SUM(V10:AG10) -> 36000000 | H10: =SUM(AH10:AS10) -> 60000000 | J10: ='01_가정'!F42*J9 -> 0 | K10: ='01_가정'!F42*K9 -> 0 | L10: ='01_가정'!F42*L9 -> 0 | M10: ='01_가정'!F42*M9 -> 0 | N10: ='01_가정'!F42*N9 -> 0 | O10: ='01_가정'!F42*O9 -> 0 | P10: ='01_가정'!F42*P9 -> 0 | Q10: ='01_가정'!F42*Q9 -> 0 | R10: ='01_가정'!F42*R9 -> 0 | S10: ='01_가정'!F42*S9 -> 750000 | T10: ='01_가정'!F42*T9 -> 1125000 | U10: ='01_가정'!F42*U9 -> 1500000 | V10: ='01_가정'!G42*V9 -> 3000000 | W10: ='01_가정'!G42*W9 -> 3000000 | X10: ='01_가정'!G42*X9 -> 3000000 | Y10: ='01_가정'!G42*Y9 -> 3000000 | Z10: ='01_가정'!G42*Z9 -> 3000000 | AA10: ='01_가정'!G42*AA9 -> 3000000 | AB10: ='01_가정'!G42*AB9 -> 3000000 | AC10: ='01_가정'!G42*AC9 -> 3000000 | AD10: ='01_가정'!G42*AD9 -> 3000000 | AE10: ='01_가정'!G42*AE9 -> 3000000 | AF10: ='01_가정'!G42*AF9 -> 3000000 | AG10: ='01_가정'!G42*AG9 -> 3000000 | AH10: ='01_가정'!H42*AH9 -> 5000000 | AI10: ='01_가정'!H42*AI9 -> 5000000 | AJ10: ='01_가정'!H42*AJ9 -> 5000000 | AK10: ='01_가정'!H42*AK9 -> 5000000 | AL10: ='01_가정'!H42*AL9 -> 5000000 | AM10: ='01_가정'!H42*AM9 -> 5000000 | AN10: ='01_가정'!H42*AN9 -> 5000000 | AO10: ='01_가정'!H42*AO9 -> 5000000 | AP10: ='01_가정'!H42*AP9 -> 5000000 | AQ10: ='01_가정'!H42*AQ9 -> 5000000 | AR10: ='01_가정'!H42*AR9 -> 5000000 | AS10: ='01_가정'!H42*AS9 -> 5000000
C11: 클릭당 비용 | D11: 원 | J11: ='01_가정'!F18 -> 1200 | K11: ='01_가정'!F18 -> 1200 | L11: ='01_가정'!F18 -> 1200 | M11: ='01_가정'!F18 -> 1200 | N11: ='01_가정'!F18 -> 1200 | O11: ='01_가정'!F18 -> 1200 | P11: ='01_가정'!F18 -> 1200 | Q11: ='01_가정'!F18 -> 1200 | R11: ='01_가정'!F18 -> 1200 | S11: ='01_가정'!F18 -> 1200 | T11: ='01_가정'!F18 -> 1200 | U11: ='01_가정'!F18 -> 1200 | V11: ='01_가정'!G18 -> 1100 | W11: ='01_가정'!G18 -> 1100 | X11: ='01_가정'!G18 -> 1100 | Y11: ='01_가정'!G18 -> 1100 | Z11: ='01_가정'!G18 -> 1100 | AA11: ='01_가정'!G18 -> 1100 | AB11: ='01_가정'!G18 -> 1100 | AC11: ='01_가정'!G18 -> 1100 | AD11: ='01_가정'!G18 -> 1100 | AE11: ='01_가정'!G18 -> 1100 | AF11: ='01_가정'!G18 -> 1100 | AG11: ='01_가정'!G18 -> 1100 | AH11: ='01_가정'!H18 -> 1000 | AI11: ='01_가정'!H18 -> 1000 | AJ11: ='01_가정'!H18 -> 1000 | AK11: ='01_가정'!H18 -> 1000 | AL11: ='01_가정'!H18 -> 1000 | AM11: ='01_가정'!H18 -> 1000 | AN11: ='01_가정'!H18 -> 1000 | AO11: ='01_가정'!H18 -> 1000 | AP11: ='01_가정'!H18 -> 1000 | AQ11: ='01_가정'!H18 -> 1000 | AR11: ='01_가정'!H18 -> 1000 | AS11: ='01_가정'!H18 -> 1000
C12: 유료 클릭 | D12: 회 | F12: =SUM(J12:U12) -> 2812.5 | G12: =SUM(V12:AG12) -> 32727.273 | H12: =SUM(AH12:AS12) -> 60000 | J12: =IF(J11>0,J10/J11,0) -> 0 | K12: =IF(K11>0,K10/K11,0) -> 0 | L12: =IF(L11>0,L10/L11,0) -> 0 | M12: =IF(M11>0,M10/M11,0) -> 0 | N12: =IF(N11>0,N10/N11,0) -> 0 | O12: =IF(O11>0,O10/O11,0) -> 0 | P12: =IF(P11>0,P10/P11,0) -> 0 | Q12: =IF(Q11>0,Q10/Q11,0) -> 0 | ... AS12: =IF(AS11>0,AS10/AS11,0) -> 5000
C13: 자연 유입 | D13: 회 | F13: =SUM(J13:U13) -> 1125 | G13: =SUM(V13:AG13) -> 12000 | H13: =SUM(AH13:AS13) -> 24000 | J13: ='01_가정'!F38*J9 -> 0 | K13: ='01_가정'!F38*K9 -> 0 | L13: ='01_가정'!F38*L9 -> 0 | M13: ='01_가정'!F38*M9 -> 0 | N13: ='01_가정'!F38*N9 -> 0 | O13: ='01_가정'!F38*O9 -> 0 | P13: ='01_가정'!F38*P9 -> 0 | Q13: ='01_가정'!F38*Q9 -> 0 | R13: ='01_가정'!F38*R9 -> 0 | S13: ='01_가정'!F38*S9 -> 250 | T13: ='01_가정'!F38*T9 -> 375 | U13: ='01_가정'!F38*U9 -> 500 | V13: ='01_가정'!G38*V9 -> 1000 | W13: ='01_가정'!G38*W9 -> 1000 | X13: ='01_가정'!G38*X9 -> 1000 | Y13: ='01_가정'!G38*Y9 -> 1000 | Z13: ='01_가정'!G38*Z9 -> 1000 | AA13: ='01_가정'!G38*AA9 -> 1000 | AB13: ='01_가정'!G38*AB9 -> 1000 | AC13: ='01_가정'!G38*AC9 -> 1000 | AD13: ='01_가정'!G38*AD9 -> 1000 | AE13: ='01_가정'!G38*AE9 -> 1000 | AF13: ='01_가정'!G38*AF9 -> 1000 | AG13: ='01_가정'!G38*AG9 -> 1000 | AH13: ='01_가정'!H38*AH9 -> 2000 | AI13: ='01_가정'!H38*AI9 -> 2000 | AJ13: ='01_가정'!H38*AJ9 -> 2000 | AK13: ='01_가정'!H38*AK9 -> 2000 | AL13: ='01_가정'!H38*AL9 -> 2000 | AM13: ='01_가정'!H38*AM9 -> 2000 | AN13: ='01_가정'!H38*AN9 -> 2000 | AO13: ='01_가정'!H38*AO9 -> 2000 | AP13: ='01_가정'!H38*AP9 -> 2000 | AQ13: ='01_가정'!H38*AQ9 -> 2000 | AR13: ='01_가정'!H38*AR9 -> 2000 | AS13: ='01_가정'!H38*AS9 -> 2000
C14: 출고 전환율 | D14: % | J14: ='01_가정'!F22 -> 0.015 | K14: ='01_가정'!F22 -> 0.015 | L14: ='01_가정'!F22 -> 0.015 | M14: ='01_가정'!F22 -> 0.015 | N14: ='01_가정'!F22 -> 0.015 | O14: ='01_가정'!F22 -> 0.015 | P14: ='01_가정'!F22 -> 0.015 | Q14: ='01_가정'!F22 -> 0.015 | R14: ='01_가정'!F22 -> 0.015 | S14: ='01_가정'!F22 -> 0.015 | T14: ='01_가정'!F22 -> 0.015 | U14: ='01_가정'!F22 -> 0.015 | V14: ='01_가정'!G22 -> 0.018 | W14: ='01_가정'!G22 -> 0.018 | X14: ='01_가정'!G22 -> 0.018 | Y14: ='01_가정'!G22 -> 0.018 | Z14: ='01_가정'!G22 -> 0.018 | AA14: ='01_가정'!G22 -> 0.018 | AB14: ='01_가정'!G22 -> 0.018 | AC14: ='01_가정'!G22 -> 0.018 | AD14: ='01_가정'!G22 -> 0.018 | AE14: ='01_가정'!G22 -> 0.018 | AF14: ='01_가정'!G22 -> 0.018 | AG14: ='01_가정'!G22 -> 0.018 | AH14: ='01_가정'!H22 -> 0.02 | AI14: ='01_가정'!H22 -> 0.02 | AJ14: ='01_가정'!H22 -> 0.02 | AK14: ='01_가정'!H22 -> 0.02 | AL14: ='01_가정'!H22 -> 0.02 | AM14: ='01_가정'!H22 -> 0.02 | AN14: ='01_가정'!H22 -> 0.02 | AO14: ='01_가정'!H22 -> 0.02 | AP14: ='01_가정'!H22 -> 0.02 | AQ14: ='01_가정'!H22 -> 0.02 | AR14: ='01_가정'!H22 -> 0.02 | AS14: ='01_가정'!H22 -> 0.02
C15: 유료 신규 출고 | D15: 개 | F15: =SUM(J15:U15) -> 41 | G15: =SUM(V15:AG15) -> 588 | H15: =SUM(AH15:AS15) -> 1200 | J15: =ROUNDDOWN(J12*J14,0) -> 0 | K15: =ROUNDDOWN(K12*K14,0) -> 0 | L15: =ROUNDDOWN(L12*L14,0) -> 0 | M15: =ROUNDDOWN(M12*M14,0) -> 0 | N15: =ROUNDDOWN(N12*N14,0) -> 0 | O15: =ROUNDDOWN(O12*O14,0) -> 0 | P15: =ROUNDDOWN(P12*P14,0) -> 0 | Q15: =ROUNDDOWN(Q12*Q14,0) -> 0 | ... AS15: =ROUNDDOWN(AS12*AS14,0) -> 100
C16: 자연 유입 신규 출고 | D16: 개 | F16: =SUM(J16:U16) -> 15 | G16: =SUM(V16:AG16) -> 216 | H16: =SUM(AH16:AS16) -> 480 | J16: =ROUNDDOWN(J13*J14,0) -> 0 | K16: =ROUNDDOWN(K13*K14,0) -> 0 | L16: =ROUNDDOWN(L13*L14,0) -> 0 | M16: =ROUNDDOWN(M13*M14,0) -> 0 | N16: =ROUNDDOWN(N13*N14,0) -> 0 | O16: =ROUNDDOWN(O13*O14,0) -> 0 | P16: =ROUNDDOWN(P13*P14,0) -> 0 | Q16: =ROUNDDOWN(Q13*Q14,0) -> 0 | ... AS16: =ROUNDDOWN(AS13*AS14,0) -> 40
C17: DTC 총 출고 | D17: 개 | F17: =SUM(J17:U17) -> 56 | G17: =SUM(V17:AG17) -> 804 | H17: =SUM(AH17:AS17) -> 1680 | J17: =SUM(J15:J16) -> 0 | K17: =SUM(K15:K16) -> 0 | L17: =SUM(L15:L16) -> 0 | M17: =SUM(M15:M16) -> 0 | N17: =SUM(N15:N16) -> 0 | O17: =SUM(O15:O16) -> 0 | P17: =SUM(P15:P16) -> 0 | Q17: =SUM(Q15:Q16) -> 0 | ... AS17: =SUM(AS15:AS16) -> 140
C18: 리테일 총 출고 | D18: 개 | F18: =SUM(J18:U18) -> 0 | G18: =SUM(V18:AG18) -> 0 | H18: =SUM(AH18:AS18) -> 0 | J18: =ROUNDDOWN('01_가정'!F50*J9*'01_가정'!$F$95,0) -> 0 | K18: =ROUNDDOWN('01_가정'!F50*K9*'01_가정'!$F$95,0) -> 0 | L18: =ROUNDDOWN('01_가정'!F50*L9*'01_가정'!$F$95,0) -> 0 | M18: =ROUNDDOWN('01_가정'!F50*M9*'01_가정'!$F$95,0) -> 0 | N18: =ROUNDDOWN('01_가정'!F50*N9*'01_가정'!$F$95,0) -> 0 | O18: =ROUNDDOWN('01_가정'!F50*O9*'01_가정'!$F$95,0) -> 0 | P18: =ROUNDDOWN('01_가정'!F50*P9*'01_가정'!$F$95,0) -> 0 | Q18: =ROUNDDOWN('01_가정'!F50*Q9*'01_가정'!$F$95,0) -> 0 | R18: =ROUNDDOWN('01_가정'!F50*R9*'01_가정'!$F$95,0) -> 0 | S18: =ROUNDDOWN('01_가정'!F50*S9*'01_가정'!$F$95,0) -> 0 | T18: =ROUNDDOWN('01_가정'!F50*T9*'01_가정'!$F$95,0) -> 0 | U18: =ROUNDDOWN('01_가정'!F50*U9*'01_가정'!$F$95,0) -> 0 | V18: =ROUNDDOWN('01_가정'!G50*V9*'01_가정'!$F$95,0) -> 0 | W18: =ROUNDDOWN('01_가정'!G50*W9*'01_가정'!$F$95,0) -> 0 | X18: =ROUNDDOWN('01_가정'!G50*X9*'01_가정'!$F$95,0) -> 0 | Y18: =ROUNDDOWN('01_가정'!G50*Y9*'01_가정'!$F$95,0) -> 0 | Z18: =ROUNDDOWN('01_가정'!G50*Z9*'01_가정'!$F$95,0) -> 0 | AA18: =ROUNDDOWN('01_가정'!G50*AA9*'01_가정'!$F$95,0) -> 0 | AB18: =ROUNDDOWN('01_가정'!G50*AB9*'01_가정'!$F$95,0) -> 0 | AC18: =ROUNDDOWN('01_가정'!G50*AC9*'01_가정'!$F$95,0) -> 0 | AD18: =ROUNDDOWN('01_가정'!G50*AD9*'01_가정'!$F$95,0) -> 0 | AE18: =ROUNDDOWN('01_가정'!G50*AE9*'01_가정'!$F$95,0) -> 0 | AF18: =ROUNDDOWN('01_가정'!G50*AF9*'01_가정'!$F$95,0) -> 0 | AG18: =ROUNDDOWN('01_가정'!G50*AG9*'01_가정'!$F$95,0) -> 0 | AH18: =ROUNDDOWN('01_가정'!H50*AH9*'01_가정'!$F$95,0) -> 0 | AI18: =ROUNDDOWN('01_가정'!H50*AI9*'01_가정'!$F$95,0) -> 0 | AJ18: =ROUNDDOWN('01_가정'!H50*AJ9*'01_가정'!$F$95,0) -> 0 | AK18: =ROUNDDOWN('01_가정'!H50*AK9*'01_가정'!$F$95,0) -> 0 | AL18: =ROUNDDOWN('01_가정'!H50*AL9*'01_가정'!$F$95,0) -> 0 | AM18: =ROUNDDOWN('01_가정'!H50*AM9*'01_가정'!$F$95,0) -> 0 | AN18: =ROUNDDOWN('01_가정'!H50*AN9*'01_가정'!$F$95,0) -> 0 | AO18: =ROUNDDOWN('01_가정'!H50*AO9*'01_가정'!$F$95,0) -> 0 | AP18: =ROUNDDOWN('01_가정'!H50*AP9*'01_가정'!$F$95,0) -> 0 | AQ18: =ROUNDDOWN('01_가정'!H50*AQ9*'01_가정'!$F$95,0) -> 0 | AR18: =ROUNDDOWN('01_가정'!H50*AR9*'01_가정'!$F$95,0) -> 0 | AS18: =ROUNDDOWN('01_가정'!H50*AS9*'01_가정'!$F$95,0) -> 0
C19: 본체 총 출고 | D19: 개 | F19: =SUM(J19:U19) -> 56 | G19: =SUM(V19:AG19) -> 804 | H19: =SUM(AH19:AS19) -> 1680 | J19: =SUM(J17:J18) -> 0 | K19: =SUM(K17:K18) -> 0 | L19: =SUM(L17:L18) -> 0 | M19: =SUM(M17:M18) -> 0 | N19: =SUM(N17:N18) -> 0 | O19: =SUM(O17:O18) -> 0 | P19: =SUM(P17:P18) -> 0 | Q19: =SUM(Q17:Q18) -> 0 | ... AS19: =SUM(AS17:AS18) -> 140
C20: DTC 환불 기대 건수 | D20: 개 | F20: =SUM(J20:U20) -> 8.4 | G20: =SUM(V20:AG20) -> 96.48 | H20: =SUM(AH20:AS20) -> 168 | J20: =J17*'01_가정'!F26 -> 0 | K20: =K17*'01_가정'!F26 -> 0 | L20: =L17*'01_가정'!F26 -> 0 | M20: =M17*'01_가정'!F26 -> 0 | N20: =N17*'01_가정'!F26 -> 0 | O20: =O17*'01_가정'!F26 -> 0 | P20: =P17*'01_가정'!F26 -> 0 | Q20: =Q17*'01_가정'!F26 -> 0 | R20: =R17*'01_가정'!F26 -> 0 | S20: =S17*'01_가정'!F26 -> 1.8 | T20: =T17*'01_가정'!F26 -> 2.85 | U20: =U17*'01_가정'!F26 -> 3.75 | V20: =V17*'01_가정'!G26 -> 8.04 | W20: =W17*'01_가정'!G26 -> 8.04 | X20: =X17*'01_가정'!G26 -> 8.04 | Y20: =Y17*'01_가정'!G26 -> 8.04 | Z20: =Z17*'01_가정'!G26 -> 8.04 | AA20: =AA17*'01_가정'!G26 -> 8.04 | AB20: =AB17*'01_가정'!G26 -> 8.04 | AC20: =AC17*'01_가정'!G26 -> 8.04 | AD20: =AD17*'01_가정'!G26 -> 8.04 | AE20: =AE17*'01_가정'!G26 -> 8.04 | AF20: =AF17*'01_가정'!G26 -> 8.04 | AG20: =AG17*'01_가정'!G26 -> 8.04 | AH20: =AH17*'01_가정'!H26 -> 14 | AI20: =AI17*'01_가정'!H26 -> 14 | AJ20: =AJ17*'01_가정'!H26 -> 14 | AK20: =AK17*'01_가정'!H26 -> 14 | AL20: =AL17*'01_가정'!H26 -> 14 | AM20: =AM17*'01_가정'!H26 -> 14 | AN20: =AN17*'01_가정'!H26 -> 14 | AO20: =AO17*'01_가정'!H26 -> 14 | AP20: =AP17*'01_가정'!H26 -> 14 | AQ20: =AQ17*'01_가정'!H26 -> 14 | AR20: =AR17*'01_가정'!H26 -> 14 | AS20: =AS17*'01_가정'!H26 -> 14
C21: DTC 비환불 고객 | D21: 명 | F21: =SUM(J21:U21) -> 47.6 | G21: =SUM(V21:AG21) -> 707.52 | H21: =SUM(AH21:AS21) -> 1512 | J21: =J17-J20 -> 0 | K21: =K17-K20 -> 0 | L21: =L17-L20 -> 0 | M21: =M17-M20 -> 0 | N21: =N17-N20 -> 0 | O21: =O17-O20 -> 0 | P21: =P17-P20 -> 0 | Q21: =Q17-Q20 -> 0 | ... AS21: =AS17-AS20 -> 126
C22: 리테일 반품 기대 건수 | D22: 개 | F22: =SUM(J22:U22) -> 0 | G22: =SUM(V22:AG22) -> 0 | H22: =SUM(AH22:AS22) -> 0 | J22: =J18*'01_가정'!$F$98 -> 0 | K22: =K18*'01_가정'!$F$98 -> 0 | L22: =L18*'01_가정'!$F$98 -> 0 | M22: =M18*'01_가정'!$F$98 -> 0 | N22: =N18*'01_가정'!$F$98 -> 0 | O22: =O18*'01_가정'!$F$98 -> 0 | P22: =P18*'01_가정'!$F$98 -> 0 | Q22: =Q18*'01_가정'!$F$98 -> 0 | ... AS22: =AS18*'01_가정'!$F$98 -> 0
C23: 총 비반품 구매자 | D23: 명 | F23: =SUM(J23:U23) -> 47.6 | G23: =SUM(V23:AG23) -> 707.52 | H23: =SUM(AH23:AS23) -> 1512 | J23: =J21+J18-J22 -> 0 | K23: =K21+K18-K22 -> 0 | L23: =L21+L18-L22 -> 0 | M23: =M21+M18-M22 -> 0 | N23: =N21+N18-N22 -> 0 | O23: =O21+O18-O22 -> 0 | P23: =P21+P18-P22 -> 0 | Q23: =Q21+Q18-Q22 -> 0 | ... AS23: =AS21+AS18-AS22 -> 126
C24: 해당 월 리필 참여율 | D24: % | J24: ='01_가정'!F30 -> 0.1 | K24: ='01_가정'!F30 -> 0.1 | L24: ='01_가정'!F30 -> 0.1 | M24: ='01_가정'!F30 -> 0.1 | N24: ='01_가정'!F30 -> 0.1 | O24: ='01_가정'!F30 -> 0.1 | P24: ='01_가정'!F30 -> 0.1 | Q24: ='01_가정'!F30 -> 0.1 | R24: ='01_가정'!F30 -> 0.1 | S24: ='01_가정'!F30 -> 0.1 | T24: ='01_가정'!F30 -> 0.1 | U24: ='01_가정'!F30 -> 0.1 | V24: ='01_가정'!G30 -> 0.12 | W24: ='01_가정'!G30 -> 0.12 | X24: ='01_가정'!G30 -> 0.12 | Y24: ='01_가정'!G30 -> 0.12 | Z24: ='01_가정'!G30 -> 0.12 | AA24: ='01_가정'!G30 -> 0.12 | AB24: ='01_가정'!G30 -> 0.12 | AC24: ='01_가정'!G30 -> 0.12 | AD24: ='01_가정'!G30 -> 0.12 | AE24: ='01_가정'!G30 -> 0.12 | AF24: ='01_가정'!G30 -> 0.12 | AG24: ='01_가정'!G30 -> 0.12 | AH24: ='01_가정'!H30 -> 0.15 | AI24: ='01_가정'!H30 -> 0.15 | AJ24: ='01_가정'!H30 -> 0.15 | AK24: ='01_가정'!H30 -> 0.15 | AL24: ='01_가정'!H30 -> 0.15 | AM24: ='01_가정'!H30 -> 0.15 | AN24: ='01_가정'!H30 -> 0.15 | AO24: ='01_가정'!H30 -> 0.15 | AP24: ='01_가정'!H30 -> 0.15 | AQ24: ='01_가정'!H30 -> 0.15 | AR24: ='01_가정'!H30 -> 0.15 | AS24: ='01_가정'!H30 -> 0.15
C25: 해당 월 리필 유지율 | D25: % | J25: ='01_가정'!F34 -> 0.75 | K25: ='01_가정'!F34 -> 0.75 | L25: ='01_가정'!F34 -> 0.75 | M25: ='01_가정'!F34 -> 0.75 | N25: ='01_가정'!F34 -> 0.75 | O25: ='01_가정'!F34 -> 0.75 | P25: ='01_가정'!F34 -> 0.75 | Q25: ='01_가정'!F34 -> 0.75 | R25: ='01_가정'!F34 -> 0.75 | S25: ='01_가정'!F34 -> 0.75 | T25: ='01_가정'!F34 -> 0.75 | U25: ='01_가정'!F34 -> 0.75 | V25: ='01_가정'!G34 -> 0.78 | W25: ='01_가정'!G34 -> 0.78 | X25: ='01_가정'!G34 -> 0.78 | Y25: ='01_가정'!G34 -> 0.78 | Z25: ='01_가정'!G34 -> 0.78 | AA25: ='01_가정'!G34 -> 0.78 | AB25: ='01_가정'!G34 -> 0.78 | AC25: ='01_가정'!G34 -> 0.78 | AD25: ='01_가정'!G34 -> 0.78 | AE25: ='01_가정'!G34 -> 0.78 | AF25: ='01_가정'!G34 -> 0.78 | AG25: ='01_가정'!G34 -> 0.78 | AH25: ='01_가정'!H34 -> 0.8 | AI25: ='01_가정'!H34 -> 0.8 | AJ25: ='01_가정'!H34 -> 0.8 | AK25: ='01_가정'!H34 -> 0.8 | AL25: ='01_가정'!H34 -> 0.8 | AM25: ='01_가정'!H34 -> 0.8 | AN25: ='01_가정'!H34 -> 0.8 | AO25: ='01_가정'!H34 -> 0.8 | AP25: ='01_가정'!H34 -> 0.8 | AQ25: ='01_가정'!H34 -> 0.8 | AR25: ='01_가정'!H34 -> 0.8 | AS25: ='01_가정'!H34 -> 0.8
C26: 신규 리필 구매자 | D26: 명 | F26: =SUM(J26:U26) -> 2.635 | G26: =SUM(V26:AG26) -> 79.9522 | H26: =SUM(AH26:AS26) -> 214.9752 | J26: =0 -> 0 | K26: =J21*J24 -> 0 | L26: =K21*K24 -> 0 | M26: =L21*L24 -> 0 | N26: =M21*M24 -> 0 | O26: =N21*N24 -> 0 | P26: =O21*O24 -> 0 | Q26: =P21*P24 -> 0 | R26: =Q21*Q24 -> 0 | ... AS26: =AR21*AR24 -> 18.9
C27: 전월 구매자 중 재구매 | D27: 명 | F27: =SUM(J27:U27) -> 0.765 | G27: =SUM(V27:AG27) -> 184.37904 | H27: =SUM(AH27:AS27) -> 624.91469 | J27: =0 -> 0 | K27: =J28*K25 -> 0 | L27: =K28*L25 -> 0 | M27: =L28*M25 -> 0 | N27: =M28*N25 -> 0 | O27: =N28*O25 -> 0 | P27: =O28*P25 -> 0 | Q27: =P28*Q25 -> 0 | R27: =Q28*R25 -> 0 | ... AS27: =AR28*AS25 -> 70.174381
C28: 당월 리필 구매자(연간=연말) | D28: 명 | F28: =U28 -> 2.38 | G28: =AG28 -> 30.327854 | H28: =AS28 -> 89.074381 | J28: =SUM(J26:J27) -> 0 | K28: =SUM(K26:K27) -> 0 | L28: =SUM(L26:L27) -> 0 | M28: =SUM(M26:M27) -> 0 | N28: =SUM(N26:N27) -> 0 | O28: =SUM(O26:O27) -> 0 | P28: =SUM(P26:P27) -> 0 | Q28: =SUM(Q26:Q27) -> 0 | ... AS28: =SUM(AS26:AS27) -> 89.074381
C29: 리필 출고 주문 | D29: 팩 | F29: =SUM(J29:U29) -> 3.4 | G29: =SUM(V29:AG29) -> 264.33124 | H29: =SUM(AH29:AS29) -> 839.88989 | J29: =J28*'01_가정'!$F$94 -> 0 | K29: =K28*'01_가정'!$F$94 -> 0 | L29: =L28*'01_가정'!$F$94 -> 0 | M29: =M28*'01_가정'!$F$94 -> 0 | N29: =N28*'01_가정'!$F$94 -> 0 | O29: =O28*'01_가정'!$F$94 -> 0 | P29: =P28*'01_가정'!$F$94 -> 0 | Q29: =Q28*'01_가정'!$F$94 -> 0 | ... AS29: =AS28*'01_가정'!$F$94 -> 89.074381
C30: DTC 본체 순매출 | D30: 원 | F30: =SUM(J30:U30) -> 5582181.8 | G30: =SUM(V30:AG30) -> 82972800 | H30: =SUM(AH30:AS30) -> 1.7731636e+08 | J30: =J21*'01_가정'!F10/(1+'01_가정'!$F$85) -> 0 | K30: =K21*'01_가정'!F10/(1+'01_가정'!$F$85) -> 0 | L30: =L21*'01_가정'!F10/(1+'01_가정'!$F$85) -> 0 | M30: =M21*'01_가정'!F10/(1+'01_가정'!$F$85) -> 0 | N30: =N21*'01_가정'!F10/(1+'01_가정'!$F$85) -> 0 | O30: =O21*'01_가정'!F10/(1+'01_가정'!$F$85) -> 0 | P30: =P21*'01_가정'!F10/(1+'01_가정'!$F$85) -> 0 | Q30: =Q21*'01_가정'!F10/(1+'01_가정'!$F$85) -> 0 | R30: =R21*'01_가정'!F10/(1+'01_가정'!$F$85) -> 0 | S30: =S21*'01_가정'!F10/(1+'01_가정'!$F$85) -> 1196181.8 | T30: =T21*'01_가정'!F10/(1+'01_가정'!$F$85) -> 1893954.5 | U30: =U21*'01_가정'!F10/(1+'01_가정'!$F$85) -> 2492045.5 | V30: =V21*'01_가정'!G10/(1+'01_가정'!$F$85) -> 6914400 | W30: =W21*'01_가정'!G10/(1+'01_가정'!$F$85) -> 6914400 | X30: =X21*'01_가정'!G10/(1+'01_가정'!$F$85) -> 6914400 | Y30: =Y21*'01_가정'!G10/(1+'01_가정'!$F$85) -> 6914400 | Z30: =Z21*'01_가정'!G10/(1+'01_가정'!$F$85) -> 6914400 | AA30: =AA21*'01_가정'!G10/(1+'01_가정'!$F$85) -> 6914400 | AB30: =AB21*'01_가정'!G10/(1+'01_가정'!$F$85) -> 6914400 | AC30: =AC21*'01_가정'!G10/(1+'01_가정'!$F$85) -> 6914400 | AD30: =AD21*'01_가정'!G10/(1+'01_가정'!$F$85) -> 6914400 | AE30: =AE21*'01_가정'!G10/(1+'01_가정'!$F$85) -> 6914400 | AF30: =AF21*'01_가정'!G10/(1+'01_가정'!$F$85) -> 6914400 | AG30: =AG21*'01_가정'!G10/(1+'01_가정'!$F$85) -> 6914400 | AH30: =AH21*'01_가정'!H10/(1+'01_가정'!$F$85) -> 14776364 | AI30: =AI21*'01_가정'!H10/(1+'01_가정'!$F$85) -> 14776364 | AJ30: =AJ21*'01_가정'!H10/(1+'01_가정'!$F$85) -> 14776364 | AK30: =AK21*'01_가정'!H10/(1+'01_가정'!$F$85) -> 14776364 | AL30: =AL21*'01_가정'!H10/(1+'01_가정'!$F$85) -> 14776364 | AM30: =AM21*'01_가정'!H10/(1+'01_가정'!$F$85) -> 14776364 | AN30: =AN21*'01_가정'!H10/(1+'01_가정'!$F$85) -> 14776364 | AO30: =AO21*'01_가정'!H10/(1+'01_가정'!$F$85) -> 14776364 | AP30: =AP21*'01_가정'!H10/(1+'01_가정'!$F$85) -> 14776364 | AQ30: =AQ21*'01_가정'!H10/(1+'01_가정'!$F$85) -> 14776364 | AR30: =AR21*'01_가정'!H10/(1+'01_가정'!$F$85) -> 14776364 | AS30: =AS21*'01_가정'!H10/(1+'01_가정'!$F$85) -> 14776364
C31: 리테일 본체 순매출 | D31: 원 | F31: =SUM(J31:U31) -> 0 | G31: =SUM(V31:AG31) -> 0 | H31: =SUM(AH31:AS31) -> 0 | J31: =(J18-J22)*'01_가정'!F10/(1+'01_가정'!$F$85)*'01_가정'!F54 -> 0 | K31: =(K18-K22)*'01_가정'!F10/(1+'01_가정'!$F$85)*'01_가정'!F54 -> 0 | L31: =(L18-L22)*'01_가정'!F10/(1+'01_가정'!$F$85)*'01_가정'!F54 -> 0 | M31: =(M18-M22)*'01_가정'!F10/(1+'01_가정'!$F$85)*'01_가정'!F54 -> 0 | N31: =(N18-N22)*'01_가정'!F10/(1+'01_가정'!$F$85)*'01_가정'!F54 -> 0 | O31: =(O18-O22)*'01_가정'!F10/(1+'01_가정'!$F$85)*'01_가정'!F54 -> 0 | P31: =(P18-P22)*'01_가정'!F10/(1+'01_가정'!$F$85)*'01_가정'!F54 -> 0 | Q31: =(Q18-Q22)*'01_가정'!F10/(1+'01_가정'!$F$85)*'01_가정'!F54 -> 0 | R31: =(R18-R22)*'01_가정'!F10/(1+'01_가정'!$F$85)*'01_가정'!F54 -> 0 | S31: =(S18-S22)*'01_가정'!F10/(1+'01_가정'!$F$85)*'01_가정'!F54 -> 0 | T31: =(T18-T22)*'01_가정'!F10/(1+'01_가정'!$F$85)*'01_가정'!F54 -> 0 | U31: =(U18-U22)*'01_가정'!F10/(1+'01_가정'!$F$85)*'01_가정'!F54 -> 0 | V31: =(V18-V22)*'01_가정'!G10/(1+'01_가정'!$F$85)*'01_가정'!G54 -> 0 | W31: =(W18-W22)*'01_가정'!G10/(1+'01_가정'!$F$85)*'01_가정'!G54 -> 0 | X31: =(X18-X22)*'01_가정'!G10/(1+'01_가정'!$F$85)*'01_가정'!G54 -> 0 | Y31: =(Y18-Y22)*'01_가정'!G10/(1+'01_가정'!$F$85)*'01_가정'!G54 -> 0 | Z31: =(Z18-Z22)*'01_가정'!G10/(1+'01_가정'!$F$85)*'01_가정'!G54 -> 0 | AA31: =(AA18-AA22)*'01_가정'!G10/(1+'01_가정'!$F$85)*'01_가정'!G54 -> 0 | AB31: =(AB18-AB22)*'01_가정'!G10/(1+'01_가정'!$F$85)*'01_가정'!G54 -> 0 | AC31: =(AC18-AC22)*'01_가정'!G10/(1+'01_가정'!$F$85)*'01_가정'!G54 -> 0 | AD31: =(AD18-AD22)*'01_가정'!G10/(1+'01_가정'!$F$85)*'01_가정'!G54 -> 0 | AE31: =(AE18-AE22)*'01_가정'!G10/(1+'01_가정'!$F$85)*'01_가정'!G54 -> 0 | AF31: =(AF18-AF22)*'01_가정'!G10/(1+'01_가정'!$F$85)*'01_가정'!G54 -> 0 | AG31: =(AG18-AG22)*'01_가정'!G10/(1+'01_가정'!$F$85)*'01_가정'!G54 -> 0 | AH31: =(AH18-AH22)*'01_가정'!H10/(1+'01_가정'!$F$85)*'01_가정'!H54 -> 0 | AI31: =(AI18-AI22)*'01_가정'!H10/(1+'01_가정'!$F$85)*'01_가정'!H54 -> 0 | AJ31: =(AJ18-AJ22)*'01_가정'!H10/(1+'01_가정'!$F$85)*'01_가정'!H54 -> 0 | AK31: =(AK18-AK22)*'01_가정'!H10/(1+'01_가정'!$F$85)*'01_가정'!H54 -> 0 | AL31: =(AL18-AL22)*'01_가정'!H10/(1+'01_가정'!$F$85)*'01_가정'!H54 -> 0 | AM31: =(AM18-AM22)*'01_가정'!H10/(1+'01_가정'!$F$85)*'01_가정'!H54 -> 0 | AN31: =(AN18-AN22)*'01_가정'!H10/(1+'01_가정'!$F$85)*'01_가정'!H54 -> 0 | AO31: =(AO18-AO22)*'01_가정'!H10/(1+'01_가정'!$F$85)*'01_가정'!H54 -> 0 | AP31: =(AP18-AP22)*'01_가정'!H10/(1+'01_가정'!$F$85)*'01_가정'!H54 -> 0 | AQ31: =(AQ18-AQ22)*'01_가정'!H10/(1+'01_가정'!$F$85)*'01_가정'!H54 -> 0 | AR31: =(AR18-AR22)*'01_가정'!H10/(1+'01_가정'!$F$85)*'01_가정'!H54 -> 0 | AS31: =(AS18-AS22)*'01_가정'!H10/(1+'01_가정'!$F$85)*'01_가정'!H54 -> 0
C32: 리필 순매출 | D32: 원 | F32: =SUM(J32:U32) -> 29988 | G32: =SUM(V32:AG32) -> 2331401.6 | H32: =SUM(AH32:AS32) -> 7407828.8 | J32: =J29*'02_단위경제'!F44 -> 0 | K32: =K29*'02_단위경제'!F44 -> 0 | L32: =L29*'02_단위경제'!F44 -> 0 | M32: =M29*'02_단위경제'!F44 -> 0 | N32: =N29*'02_단위경제'!F44 -> 0 | O32: =O29*'02_단위경제'!F44 -> 0 | P32: =P29*'02_단위경제'!F44 -> 0 | Q32: =Q29*'02_단위경제'!F44 -> 0 | R32: =R29*'02_단위경제'!F44 -> 0 | S32: =S29*'02_단위경제'!F44 -> 0 | T32: =T29*'02_단위경제'!F44 -> 8996.4 | U32: =U29*'02_단위경제'!F44 -> 20991.6 | V32: =V29*'02_단위경제'!G44 -> 35115.948 | W32: =W29*'02_단위경제'!G44 -> 89793.703 | X32: =X29*'02_단위경제'!G44 -> 132442.35 | Y32: =Y29*'02_단위경제'!G44 -> 165708.3 | Z32: =Z29*'02_단위경제'!G44 -> 191655.74 | AA32: =AA29*'02_단위경제'!G44 -> 211894.74 | AB32: =AB29*'02_단위경제'!G44 -> 227681.16 | AC32: =AC29*'02_단위경제'!G44 -> 239994.57 | AD32: =AD29*'02_단위경제'!G44 -> 249599.03 | AE32: =AE29*'02_단위경제'!G44 -> 257090.51 | AF32: =AF29*'02_단위경제'!G44 -> 262933.86 | AG32: =AG29*'02_단위경제'!G44 -> 267491.67 | AH32: =AH29*'02_단위경제'!H44 -> 276396.6 | AI32: =AI29*'02_단위경제'!H44 -> 387815.28 | AJ32: =AJ29*'02_단위경제'!H44 -> 476950.23 | AK32: =AK29*'02_단위경제'!H44 -> 548258.18 | AL32: =AL29*'02_단위경제'!H44 -> 605304.54 | AM32: =AM29*'02_단위경제'!H44 -> 650941.64 | AN32: =AN29*'02_단위경제'!H44 -> 687451.31 | AO32: =AO29*'02_단위경제'!H44 -> 716659.05 | AP32: =AP29*'02_단위경제'!H44 -> 740025.24 | AQ32: =AQ29*'02_단위경제'!H44 -> 758718.19 | AR32: =AR29*'02_단위경제'!H44 -> 773672.55 | AS32: =AS29*'02_단위경제'!H44 -> 785636.04
C33: 총 순매출 | D33: 원 | F33: =SUM(J33:U33) -> 5612169.8 | G33: =SUM(V33:AG33) -> 85304202 | H33: =SUM(AH33:AS33) -> 1.8472419e+08 | J33: =SUM(J30:J32) -> 0 | K33: =SUM(K30:K32) -> 0 | L33: =SUM(L30:L32) -> 0 | M33: =SUM(M30:M32) -> 0 | N33: =SUM(N30:N32) -> 0 | O33: =SUM(O30:O32) -> 0 | P33: =SUM(P30:P32) -> 0 | Q33: =SUM(Q30:Q32) -> 0 | ... AS33: =SUM(AS30:AS32) -> 15562000
C34: 본체 매출원가 | D34: 원 | F34: =SUM(J34:U34) -> 3920000 | G34: =SUM(V34:AG34) -> 53370875 | H34: =SUM(AH34:AS34) -> 1.0259593e+08 | J34: ='04_재고현금'!J16 -> 0 | K34: ='04_재고현금'!K16 -> 0 | L34: ='04_재고현금'!L16 -> 0 | M34: ='04_재고현금'!M16 -> 0 | N34: ='04_재고현금'!N16 -> 0 | O34: ='04_재고현금'!O16 -> 0 | P34: ='04_재고현금'!P16 -> 0 | Q34: ='04_재고현금'!Q16 -> 0 | ... AS34: ='04_재고현금'!AS16 -> 8411547
C35: 리필 매출원가 | D35: 원 | F35: =SUM(J35:U35) -> 15300 | G35: =SUM(V35:AG35) -> 1136624.4 | H35: =SUM(AH35:AS35) -> 3359559.6 | J35: =J29*'01_가정'!F74 -> 0 | K35: =K29*'01_가정'!F74 -> 0 | L35: =L29*'01_가정'!F74 -> 0 | M35: =M29*'01_가정'!F74 -> 0 | N35: =N29*'01_가정'!F74 -> 0 | O35: =O29*'01_가정'!F74 -> 0 | P35: =P29*'01_가정'!F74 -> 0 | Q35: =Q29*'01_가정'!F74 -> 0 | R35: =R29*'01_가정'!F74 -> 0 | S35: =S29*'01_가정'!F74 -> 0 | T35: =T29*'01_가정'!F74 -> 4590 | U35: =U29*'01_가정'!F74 -> 10710 | V35: =V29*'01_가정'!G74 -> 17120.02 | W35: =W29*'01_가정'!G74 -> 43776.976 | X35: =X29*'01_가정'!G74 -> 64569.401 | Y35: =Y29*'01_가정'!G74 -> 80787.493 | Z35: =Z29*'01_가정'!G74 -> 93437.604 | AA35: =AA29*'01_가정'!G74 -> 103304.69 | AB35: =AB29*'01_가정'!G74 -> 111001.02 | AC35: =AC29*'01_가정'!G74 -> 117004.16 | AD35: =AD29*'01_가정'!G74 -> 121686.6 | AE35: =AE29*'01_가정'!G74 -> 125338.91 | AF35: =AF29*'01_가정'!G74 -> 128187.71 | AG35: =AG29*'01_가정'!G74 -> 130409.77 | AH35: =AH29*'01_가정'!H74 -> 125349.93 | AI35: =AI29*'01_가정'!H74 -> 175879.95 | AJ35: =AJ29*'01_가정'!H74 -> 216303.96 | AK35: =AK29*'01_가정'!H74 -> 248643.17 | AL35: =AL29*'01_가정'!H74 -> 274514.53 | AM35: =AM29*'01_가정'!H74 -> 295211.63 | AN35: =AN29*'01_가정'!H74 -> 311769.3 | AO35: =AO29*'01_가정'!H74 -> 325015.44 | AP35: =AP29*'01_가정'!H74 -> 335612.35 | AQ35: =AQ29*'01_가정'!H74 -> 344089.88 | AR35: =AR29*'01_가정'!H74 -> 350871.91 | AS35: =AS29*'01_가정'!H74 -> 356297.52
C36: 매출총이익 | D36: 원 | F36: =SUM(J36:U36) -> 1676869.8 | G36: =SUM(V36:AG36) -> 30796703 | H36: =SUM(AH36:AS36) -> 78768704 | J36: =J33-SUM(J34:J35) -> 0 | K36: =K33-SUM(K34:K35) -> 0 | L36: =L33-SUM(L34:L35) -> 0 | M36: =M33-SUM(M34:M35) -> 0 | N36: =N33-SUM(N34:N35) -> 0 | O36: =O33-SUM(O34:O35) -> 0 | P36: =P33-SUM(P34:P35) -> 0 | Q36: =Q33-SUM(Q34:Q35) -> 0 | ... AS36: =AS33-SUM(AS34:AS35) -> 6794155.2
C37: DTC 결제 수수료 | D37: 원 | F37: =SUM(J37:U37) -> 184212 | G37: =SUM(V37:AG37) -> 2738102.4 | H37: =SUM(AH37:AS37) -> 5851440 | J37: =J30*'01_가정'!$F$86 -> 0 | K37: =K30*'01_가정'!$F$86 -> 0 | L37: =L30*'01_가정'!$F$86 -> 0 | M37: =M30*'01_가정'!$F$86 -> 0 | N37: =N30*'01_가정'!$F$86 -> 0 | O37: =O30*'01_가정'!$F$86 -> 0 | P37: =P30*'01_가정'!$F$86 -> 0 | Q37: =Q30*'01_가정'!$F$86 -> 0 | ... AS37: =AS30*'01_가정'!$F$86 -> 487620
C38: 본체 DTC 물류비 | D38: 원 | F38: =SUM(J38:U38) -> 252000 | G38: =SUM(V38:AG38) -> 3618000 | H38: =SUM(AH38:AS38) -> 7560000 | J38: =J17*'01_가정'!$F$87 -> 0 | K38: =K17*'01_가정'!$F$87 -> 0 | L38: =L17*'01_가정'!$F$87 -> 0 | M38: =M17*'01_가정'!$F$87 -> 0 | N38: =N17*'01_가정'!$F$87 -> 0 | O38: =O17*'01_가정'!$F$87 -> 0 | P38: =P17*'01_가정'!$F$87 -> 0 | Q38: =Q17*'01_가정'!$F$87 -> 0 | ... AS38: =AS17*'01_가정'!$F$87 -> 630000
C39: 본체 반품 처리비 | D39: 원 | F39: =SUM(J39:U39) -> 50400 | G39: =SUM(V39:AG39) -> 578880 | H39: =SUM(AH39:AS39) -> 1008000 | J39: =SUM(J20,J22)*'01_가정'!$F$88 -> 0 | K39: =SUM(K20,K22)*'01_가정'!$F$88 -> 0 | L39: =SUM(L20,L22)*'01_가정'!$F$88 -> 0 | M39: =SUM(M20,M22)*'01_가정'!$F$88 -> 0 | N39: =SUM(N20,N22)*'01_가정'!$F$88 -> 0 | O39: =SUM(O20,O22)*'01_가정'!$F$88 -> 0 | P39: =SUM(P20,P22)*'01_가정'!$F$88 -> 0 | Q39: =SUM(Q20,Q22)*'01_가정'!$F$88 -> 0 | ... AS39: =SUM(AS20,AS22)*'01_가정'!$F$88 -> 84000
C40: 본체 AS 기대비용 | D40: 원 | F40: =SUM(J40:U40) -> 112000 | G40: =SUM(V40:AG40) -> 1608000 | H40: =SUM(AH40:AS40) -> 3360000 | J40: =J19*'01_가정'!$F$89 -> 0 | K40: =K19*'01_가정'!$F$89 -> 0 | L40: =L19*'01_가정'!$F$89 -> 0 | M40: =M19*'01_가정'!$F$89 -> 0 | N40: =N19*'01_가정'!$F$89 -> 0 | O40: =O19*'01_가정'!$F$89 -> 0 | P40: =P19*'01_가정'!$F$89 -> 0 | Q40: =Q19*'01_가정'!$F$89 -> 0 | ... AS40: =AS19*'01_가정'!$F$89 -> 280000
C41: 본체 변동 상담비 | D41: 원 | F41: =SUM(J41:U41) -> 56000 | G41: =SUM(V41:AG41) -> 804000 | H41: =SUM(AH41:AS41) -> 1680000 | J41: =J19*'01_가정'!$F$90 -> 0 | K41: =K19*'01_가정'!$F$90 -> 0 | L41: =L19*'01_가정'!$F$90 -> 0 | M41: =M19*'01_가정'!$F$90 -> 0 | N41: =N19*'01_가정'!$F$90 -> 0 | O41: =O19*'01_가정'!$F$90 -> 0 | P41: =P19*'01_가정'!$F$90 -> 0 | Q41: =Q19*'01_가정'!$F$90 -> 0 | ... AS41: =AS19*'01_가정'!$F$90 -> 140000
C42: 리테일 물류비 | D42: 원 | F42: =SUM(J42:U42) -> 0 | G42: =SUM(V42:AG42) -> 0 | H42: =SUM(AH42:AS42) -> 0 | J42: =J18*'01_가정'!$F$97 -> 0 | K42: =K18*'01_가정'!$F$97 -> 0 | L42: =L18*'01_가정'!$F$97 -> 0 | M42: =M18*'01_가정'!$F$97 -> 0 | N42: =N18*'01_가정'!$F$97 -> 0 | O42: =O18*'01_가정'!$F$97 -> 0 | P42: =P18*'01_가정'!$F$97 -> 0 | Q42: =Q18*'01_가정'!$F$97 -> 0 | ... AS42: =AS18*'01_가정'!$F$97 -> 0
C43: 리필 결제 수수료 | D43: 원 | F43: =SUM(J43:U43) -> 989.604 | G43: =SUM(V43:AG43) -> 76936.252 | H43: =SUM(AH43:AS43) -> 244458.35 | J43: =J32*'01_가정'!$F$92 -> 0 | K43: =K32*'01_가정'!$F$92 -> 0 | L43: =L32*'01_가정'!$F$92 -> 0 | M43: =M32*'01_가정'!$F$92 -> 0 | N43: =N32*'01_가정'!$F$92 -> 0 | O43: =O32*'01_가정'!$F$92 -> 0 | P43: =P32*'01_가정'!$F$92 -> 0 | Q43: =Q32*'01_가정'!$F$92 -> 0 | ... AS43: =AS32*'01_가정'!$F$92 -> 25925.989
...

Sheet 04_재고현금
C2: 발주 재고와 36개월 현금 계획
C4: 선택 시나리오 | F4: ='01_가정'!H4 -> 보수
F5: 1년차 | G5: 2년차 | H5: 3년차 | J5: =EDATE('01_가정'!$F$5,0) -> 46388 | K5: =EDATE('01_가정'!$F$5,1) -> 46419 | L5: =EDATE('01_가정'!$F$5,2) -> 46447 | M5: =EDATE('01_가정'!$F$5,3) -> 46478 | N5: =EDATE('01_가정'!$F$5,4) -> 46508 | O5: =EDATE('01_가정'!$F$5,5) -> 46539 | P5: =EDATE('01_가정'!$F$5,6) -> 46569 | Q5: =EDATE('01_가정'!$F$5,7) -> 46600 | R5: =EDATE('01_가정'!$F$5,8) -> 46631 | S5: =EDATE('01_가정'!$F$5,9) -> 46661 | T5: =EDATE('01_가정'!$F$5,10) -> 46692 | U5: =EDATE('01_가정'!$F$5,11) -> 46722 | V5: =EDATE('01_가정'!$F$5,12) -> 46753 | W5: =EDATE('01_가정'!$F$5,13) -> 46784 | X5: =EDATE('01_가정'!$F$5,14) -> 46813 | Y5: =EDATE('01_가정'!$F$5,15) -> 46844 | Z5: =EDATE('01_가정'!$F$5,16) -> 46874 | AA5: =EDATE('01_가정'!$F$5,17) -> 46905 | AB5: =EDATE('01_가정'!$F$5,18) -> 46935 | AC5: =EDATE('01_가정'!$F$5,19) -> 46966 | AD5: =EDATE('01_가정'!$F$5,20) -> 46997 | AE5: =EDATE('01_가정'!$F$5,21) -> 47027 | AF5: =EDATE('01_가정'!$F$5,22) -> 47058 | AG5: =EDATE('01_가정'!$F$5,23) -> 47088 | AH5: =EDATE('01_가정'!$F$5,24) -> 47119 | AI5: =EDATE('01_가정'!$F$5,25) -> 47150 | AJ5: =EDATE('01_가정'!$F$5,26) -> 47178 | AK5: =EDATE('01_가정'!$F$5,27) -> 47209 | AL5: =EDATE('01_가정'!$F$5,28) -> 47239 | AM5: =EDATE('01_가정'!$F$5,29) -> 47270 | AN5: =EDATE('01_가정'!$F$5,30) -> 47300 | AO5: =EDATE('01_가정'!$F$5,31) -> 47331 | AP5: =EDATE('01_가정'!$F$5,32) -> 47362 | AQ5: =EDATE('01_가정'!$F$5,33) -> 47392 | AR5: =EDATE('01_가정'!$F$5,34) -> 47423 | AS5: =EDATE('01_가정'!$F$5,35) -> 47453
J6: 1 | K6: 2 | L6: 3 | M6: 4 | N6: 5 | O6: 6 | P6: 7 | Q6: 8 | R6: 9 | S6: 10 | T6: 11 | U6: 12 | V6: 13 | W6: 14 | X6: 15 | Y6: 16 | Z6: 17 | AA6: 18 | AB6: 19 | AC6: 20 | AD6: 21 | AE6: 22 | AF6: 23 | AG6: 24 | AH6: 25 | AI6: 26 | AJ6: 27 | AK6: 28 | AL6: 29 | AM6: 30 | AN6: 31 | AO6: 32 | AP6: 33 | AQ6: 34 | AR6: 35 | AS6: 36
C8: 본체 출고 | D8: 개 | F8: =SUM(J8:U8) -> 56 | G8: =SUM(V8:AG8) -> 804 | H8: =SUM(AH8:AS8) -> 1680 | J8: ='03_월별손익'!J19 -> 0 | K8: ='03_월별손익'!K19 -> 0 | L8: ='03_월별손익'!L19 -> 0 | M8: ='03_월별손익'!M19 -> 0 | N8: ='03_월별손익'!N19 -> 0 | O8: ='03_월별손익'!O19 -> 0 | P8: ='03_월별손익'!P19 -> 0 | Q8: ='03_월별손익'!Q19 -> 0 | ... AS8: ='03_월별손익'!AS19 -> 140
C9: 기초 재고 수량 | D9: 개 | F9: =J9 -> 0 | G9: =V9 -> 244 | H9: =AH9 -> 340 | J9: =0 -> 0 | K9: =J11 -> 0 | L9: =K11 -> 0 | M9: =L11 -> 0 | N9: =M11 -> 0 | O9: =N11 -> 0 | P9: =O11 -> 0 | Q9: =P11 -> 0 | R9: =Q11 -> 0 | ... AS9: =AR11 -> 300
C10: 제품 입고 수량 | D10: 개 | F10: =SUM(J10:U10) -> 300 | G10: =SUM(V10:AG10) -> 900 | H10: =SUM(AH10:AS10) -> 1500 | J10: =IF(AND(J$6>='01_가정'!F46,MOD(J$6-'01_가정'!F46,3)=0),MAX(0,ROUNDUP((SUM('03_월별손익'!J19:L19)+'01_가정'!$F$100-J9)/'01_가정'!$F$99,0)*'01_가정'!$F$99),0) -> 0 | K10: =IF(AND(K$6>='01_가정'!F46,MOD(K$6-'01_가정'!F46,3)=0),MAX(0,ROUNDUP((SUM('03_월별손익'!K19:M19)+'01_가정'!$F$100-K9)/'01_가정'!$F$99,0)*'01_가정'!$F$99),0) -> 0 | L10: =IF(AND(L$6>='01_가정'!F46,MOD(L$6-'01_가정'!F46,3)=0),MAX(0,ROUNDUP((SUM('03_월별손익'!L19:N19)+'01_가정'!$F$100-L9)/'01_가정'!$F$99,0)*'01_가정'!$F$99),0) -> 0 | M10: =IF(AND(M$6>='01_가정'!F46,MOD(M$6-'01_가정'!F46,3)=0),MAX(0,ROUNDUP((SUM('03_월별손익'!M19:O19)+'01_가정'!$F$100-M9)/'01_가정'!$F$99,0)*'01_가정'!$F$99),0) -> 0 | N10: =IF(AND(N$6>='01_가정'!F46,MOD(N$6-'01_가정'!F46,3)=0),MAX(0,ROUNDUP((SUM('03_월별손익'!N19:P19)+'01_가정'!$F$100-N9)/'01_가정'!$F$99,0)*'01_가정'!$F$99),0) -> 0 | O10: =IF(AND(O$6>='01_가정'!F46,MOD(O$6-'01_가정'!F46,3)=0),MAX(0,ROUNDUP((SUM('03_월별손익'!O19:Q19)+'01_가정'!$F$100-O9)/'01_가정'!$F$99,0)*'01_가정'!$F$99),0) -> 0 | P10: =IF(AND(P$6>='01_가정'!F46,MOD(P$6-'01_가정'!F46,3)=0),MAX(0,ROUNDUP((SUM('03_월별손익'!P19:R19)+'01_가정'!$F$100-P9)/'01_가정'!$F$99,0)*'01_가정'!$F$99),0) -> 0 | Q10: =IF(AND(Q$6>='01_가정'!F46,MOD(Q$6-'01_가정'!F46,3)=0),MAX(0,ROUNDUP((SUM('03_월별손익'!Q19:S19)+'01_가정'!$F$100-Q9)/'01_가정'!$F$99,0)*'01_가정'!$F$99),0) -> 0 | R10: =IF(AND(R$6>='01_가정'!F46,MOD(R$6-'01_가정'!F46,3)=0),MAX(0,ROUNDUP((SUM('03_월별손익'!R19:T19)+'01_가정'!$F$100-R9)/'01_가정'!$F$99,0)*'01_가정'!$F$99),0) -> 0 | S10: =IF(AND(S$6>='01_가정'!F46,MOD(S$6-'01_가정'!F46,3)=0),MAX(0,ROUNDUP((SUM('03_월별손익'!S19:U19)+'01_가정'!$F$100-S9)/'01_가정'!$F$99,0)*'01_가정'!$F$99),0) -> 300 | T10: =IF(AND(T$6>='01_가정'!F46,MOD(T$6-'01_가정'!F46,3)=0),MAX(0,ROUNDUP((SUM('03_월별손익'!T19:V19)+'01_가정'!$F$100-T9)/'01_가정'!$F$99,0)*'01_가정'!$F$99),0) -> 0 | U10: =IF(AND(U$6>='01_가정'!F46,MOD(U$6-'01_가정'!F46,3)=0),MAX(0,ROUNDUP((SUM('03_월별손익'!U19:W19)+'01_가정'!$F$100-U9)/'01_가정'!$F$99,0)*'01_가정'!$F$99),0) -> 0 | V10: =IF(AND(V$6>='01_가정'!F46,MOD(V$6-'01_가정'!F46,3)=0),MAX(0,ROUNDUP((SUM('03_월별손익'!V19:X19)+'01_가정'!$F$100-V9)/'01_가정'!$F$99,0)*'01_가정'!$F$99),0) -> 300 | W10: =IF(AND(W$6>='01_가정'!F46,MOD(W$6-'01_가정'!F46,3)=0),MAX(0,ROUNDUP((SUM('03_월별손익'!W19:Y19)+'01_가정'!$F$100-W9)/'01_가정'!$F$99,0)*'01_가정'!$F$99),0) -> 0 | X10: =IF(AND(X$6>='01_가정'!F46,MOD(X$6-'01_가정'!F46,3)=0),MAX(0,ROUNDUP((SUM('03_월별손익'!X19:Z19)+'01_가정'!$F$100-X9)/'01_가정'!$F$99,0)*'01_가정'!$F$99),0) -> 0 | Y10: =IF(AND(Y$6>='01_가정'!F46,MOD(Y$6-'01_가정'!F46,3)=0),MAX(0,ROUNDUP((SUM('03_월별손익'!Y19:AA19)+'01_가정'!$F$100-Y9)/'01_가정'!$F$99,0)*'01_가정'!$F$99),0) -> 0 | Z10: =IF(AND(Z$6>='01_가정'!F46,MOD(Z$6-'01_가정'!F46,3)=0),MAX(0,ROUNDUP((SUM('03_월별손익'!Z19:AB19)+'01_가정'!$F$100-Z9)/'01_가정'!$F$99,0)*'01_가정'!$F$99),0) -> 0 | AA10: =IF(AND(AA$6>='01_가정'!F46,MOD(AA$6-'01_가정'!F46,3)=0),MAX(0,ROUNDUP((SUM('03_월별손익'!AA19:AC19)+'01_가정'!$F$100-AA9)/'01_가정'!$F$99,0)*'01_가정'!$F$99),0) -> 0 | AB10: =IF(AND(AB$6>='01_가정'!F46,MOD(AB$6-'01_가정'!F46,3)=0),MAX(0,ROUNDUP((SUM('03_월별손익'!AB19:AD19)+'01_가정'!$F$100-AB9)/'01_가정'!$F$99,0)*'01_가정'!$F$99),0) -> 300 | AC10: =IF(AND(AC$6>='01_가정'!F46,MOD(AC$6-'01_가정'!F46,3)=0),MAX(0,ROUNDUP((SUM('03_월별손익'!AC19:AE19)+'01_가정'!$F$100-AC9)/'01_가정'!$F$99,0)*'01_가정'!$F$99),0) -> 0 | AD10: =IF(AND(AD$6>='01_가정'!F46,MOD(AD$6-'01_가정'!F46,3)=0),MAX(0,ROUNDUP((SUM('03_월별손익'!AD19:AF19)+'01_가정'!$F$100-AD9)/'01_가정'!$F$99,0)*'01_가정'!$F$99),0) -> 0 | AE10: =IF(AND(AE$6>='01_가정'!F46,MOD(AE$6-'01_가정'!F46,3)=0),MAX(0,ROUNDUP((SUM('03_월별손익'!AE19:AG19)+'01_가정'!$F$100-AE9)/'01_가정'!$F$99,0)*'01_가정'!$F$99),0) -> 300 | AF10: =IF(AND(AF$6>='01_가정'!F46,MOD(AF$6-'01_가정'!F46,3)=0),MAX(0,ROUNDUP((SUM('03_월별손익'!AF19:AH19)+'01_가정'!$F$100-AF9)/'01_가정'!$F$99,0)*'01_가정'!$F$99),0) -> 0 | AG10: =IF(AND(AG$6>='01_가정'!F46,MOD(AG$6-'01_가정'!F46,3)=0),MAX(0,ROUNDUP((SUM('03_월별손익'!AG19:AI19)+'01_가정'!$F$100-AG9)/'01_가정'!$F$99,0)*'01_가정'!$F$99),0) -> 0 | AH10: =IF(AND(AH$6>='01_가정'!F46,MOD(AH$6-'01_가정'!F46,3)=0),MAX(0,ROUNDUP((SUM('03_월별손익'!AH19:AJ19)+'01_가정'!$F$100-AH9)/'01_가정'!$F$99,0)*'01_가정'!$F$99),0) -> 300 | AI10: =IF(AND(AI$6>='01_가정'!F46,MOD(AI$6-'01_가정'!F46,3)=0),MAX(0,ROUNDUP((SUM('03_월별손익'!AI19:AK19)+'01_가정'!$F$100-AI9)/'01_가정'!$F$99,0)*'01_가정'!$F$99),0) -> 0 | AJ10: =IF(AND(AJ$6>='01_가정'!F46,MOD(AJ$6-'01_가정'!F46,3)=0),MAX(0,ROUNDUP((SUM('03_월별손익'!AJ19:AL19)+'01_가정'!$F$100-AJ9)/'01_가정'!$F$99,0)*'01_가정'!$F$99),0) -> 0 | AK10: =IF(AND(AK$6>='01_가정'!F46,MOD(AK$6-'01_가정'!F46,3)=0),MAX(0,ROUNDUP((SUM('03_월별손익'!AK19:AM19)+'01_가정'!$F$100-AK9)/'01_가정'!$F$99,0)*'01_가정'!$F$99),0) -> 300 | AL10: =IF(AND(AL$6>='01_가정'!F46,MOD(AL$6-'01_가정'!F46,3)=0),MAX(0,ROUNDUP((SUM('03_월별손익'!AL19:AN19)+'01_가정'!$F$100-AL9)/'01_가정'!$F$99,0)*'01_가정'!$F$99),0) -> 0 | AM10: =IF(AND(AM$6>='01_가정'!F46,MOD(AM$6-'01_가정'!F46,3)=0),MAX(0,ROUNDUP((SUM('03_월별손익'!AM19:AO19)+'01_가정'!$F$100-AM9)/'01_가정'!$F$99,0)*'01_가정'!$F$99),0) -> 0 | AN10: =IF(AND(AN$6>='01_가정'!F46,MOD(AN$6-'01_가정'!F46,3)=0),MAX(0,ROUNDUP((SUM('03_월별손익'!AN19:AP19)+'01_가정'!$F$100-AN9)/'01_가정'!$F$99,0)*'01_가정'!$F$99),0) -> 600 | AO10: =IF(AND(AO$6>='01_가정'!F46,MOD(AO$6-'01_가정'!F46,3)=0),MAX(0,ROUNDUP((SUM('03_월별손익'!AO19:AQ19)+'01_가정'!$F$100-AO9)/'01_가정'!$F$99,0)*'01_가정'!$F$99),0) -> 0 | AP10: =IF(AND(AP$6>='01_가정'!F46,MOD(AP$6-'01_가정'!F46,3)=0),MAX(0,ROUNDUP((SUM('03_월별손익'!AP19:AR19)+'01_가정'!$F$100-AP9)/'01_가정'!$F$99,0)*'01_가정'!$F$99),0) -> 0 | AQ10: =IF(AND(AQ$6>='01_가정'!F46,MOD(AQ$6-'01_가정'!F46,3)=0),MAX(0,ROUNDUP((SUM('03_월별손익'!AQ19:AS19)+'01_가정'!$F$100-AQ9)/'01_가정'!$F$99,0)*'01_가정'!$F$99),0) -> 300 | AR10: =IF(AND(AR$6>='01_가정'!F46,MOD(AR$6-'01_가정'!F46,3)=0),MAX(0,ROUNDUP((SUM('03_월별손익'!AR19:AS19)+'01_가정'!$F$100-AR9)/'01_가정'!$F$99,0)*'01_가정'!$F$99),0) -> 0 | AS10: =IF(AND(AS$6>='01_가정'!F46,MOD(AS$6-'01_가정'!F46,3)=0),MAX(0,ROUNDUP((SUM('03_월별손익'!AS19:AS19)+'01_가정'!$F$100-AS9)/'01_가정'!$F$99,0)*'01_가정'!$F$99),0) -> 0
C11: 기말 재고 수량 | D11: 개 | F11: =U11 -> 244 | G11: =AG11 -> 340 | H11: =AS11 -> 160 | J11: =J9+J10-J8 -> 0 | K11: =K9+K10-K8 -> 0 | L11: =L9+L10-L8 -> 0 | M11: =M9+M10-M8 -> 0 | N11: =N9+N10-N8 -> 0 | O11: =O9+O10-O8 -> 0 | P11: =P9+P10-P8 -> 0 | Q11: =Q9+Q10-Q8 -> 0 | ... AS11: =AS9+AS10-AS8 -> 160
C12: 입고월 적용 제조단가 | D12: 원 | J12: ='01_가정'!F14 -> 70000 | K12: ='01_가정'!F14 -> 70000 | L12: ='01_가정'!F14 -> 70000 | M12: ='01_가정'!F14 -> 70000 | N12: ='01_가정'!F14 -> 70000 | O12: ='01_가정'!F14 -> 70000 | P12: ='01_가정'!F14 -> 70000 | Q12: ='01_가정'!F14 -> 70000 | R12: ='01_가정'!F14 -> 70000 | S12: ='01_가정'!F14 -> 70000 | T12: ='01_가정'!F14 -> 70000 | U12: ='01_가정'!F14 -> 70000 | V12: ='01_가정'!G14 -> 65000 | W12: ='01_가정'!G14 -> 65000 | X12: ='01_가정'!G14 -> 65000 | Y12: ='01_가정'!G14 -> 65000 | Z12: ='01_가정'!G14 -> 65000 | AA12: ='01_가정'!G14 -> 65000 | AB12: ='01_가정'!G14 -> 65000 | AC12: ='01_가정'!G14 -> 65000 | AD12: ='01_가정'!G14 -> 65000 | AE12: ='01_가정'!G14 -> 65000 | AF12: ='01_가정'!G14 -> 65000 | AG12: ='01_가정'!G14 -> 65000 | AH12: ='01_가정'!H14 -> 60000 | AI12: ='01_가정'!H14 -> 60000 | AJ12: ='01_가정'!H14 -> 60000 | AK12: ='01_가정'!H14 -> 60000 | AL12: ='01_가정'!H14 -> 60000 | AM12: ='01_가정'!H14 -> 60000 | AN12: ='01_가정'!H14 -> 60000 | AO12: ='01_가정'!H14 -> 60000 | AP12: ='01_가정'!H14 -> 60000 | AQ12: ='01_가정'!H14 -> 60000 | AR12: ='01_가정'!H14 -> 60000 | AS12: ='01_가정'!H14 -> 60000
C13: 입고 제품 공급가 합계 | D13: 원 | F13: =SUM(J13:U13) -> 21000000 | G13: =SUM(V13:AG13) -> 58500000 | H13: =SUM(AH13:AS13) -> 90000000 | J13: =J10*J12 -> 0 | K13: =K10*K12 -> 0 | L13: =L10*L12 -> 0 | M13: =M10*M12 -> 0 | N13: =N10*N12 -> 0 | O13: =O10*O12 -> 0 | P13: =P10*P12 -> 0 | Q13: =Q10*Q12 -> 0 | ... AS13: =AS10*AS12 -> 0
C14: 기초 재고 금액 | D14: 원 | F14: =J14 -> 0 | G14: =V14 -> 17080000 | H14: =AH14 -> 22209125 | J14: =0 -> 0 | K14: =J17 -> 0 | L14: =K17 -> 0 | M14: =L17 -> 0 | N14: =M17 -> 0 | O14: =N17 -> 0 | P14: =O17 -> 0 | Q14: =P17 -> 0 | R14: =Q17 -> 0 | ... AS14: =AR17 -> 18024744
C15: 이동평균 원가 | D15: 원 | J15: =IF(SUM(J9:J10)>0,(J14+J13)/SUM(J9:J10),0) -> 0 | K15: =IF(SUM(K9:K10)>0,(K14+K13)/SUM(K9:K10),0) -> 0 | L15: =IF(SUM(L9:L10)>0,(L14+L13)/SUM(L9:L10),0) -> 0 | M15: =IF(SUM(M9:M10)>0,(M14+M13)/SUM(M9:M10),0) -> 0 | N15: =IF(SUM(N9:N10)>0,(N14+N13)/SUM(N9:N10),0) -> 0 | O15: =IF(SUM(O9:O10)>0,(O14+O13)/SUM(O9:O10),0) -> 0 | P15: =IF(SUM(P9:P10)>0,(P14+P13)/SUM(P9:P10),0) -> 0 | Q15: =IF(SUM(Q9:Q10)>0,(Q14+Q13)/SUM(Q9:Q10),0) -> 0 | ... AS15: =IF(SUM(AS9:AS10)>0,(AS14+AS13)/SUM(AS9:AS10),0) -> 60082.478
C16: 출고 매출원가 | D16: 원 | F16: =SUM(J16:U16) -> 3920000 | G16: =SUM(V16:AG16) -> 53370875 | H16: =SUM(AH16:AS16) -> 1.0259593e+08 | J16: =J8*J15 -> 0 | K16: =K8*K15 -> 0 | L16: =L8*L15 -> 0 | M16: =M8*M15 -> 0 | N16: =N8*N15 -> 0 | O16: =O8*O15 -> 0 | P16: =P8*P15 -> 0 | Q16: =Q8*Q15 -> 0 | ... AS16: =AS8*AS15 -> 8411547
C17: 기말 재고 금액 | D17: 원 | F17: =U17 -> 17080000 | G17: =AG17 -> 22209125 | H17: =AS17 -> 9613196.5 | J17: =J14+J13-J16 -> 0 | K17: =K14+K13-K16 -> 0 | L17: =L14+L13-L16 -> 0 | M17: =M14+M13-M16 -> 0 | N17: =N14+N13-N16 -> 0 | O17: =O14+O13-O16 -> 0 | P17: =P14+P13-P16 -> 0 | Q17: =Q14+Q13-Q16 -> 0 | ... AS17: =AS14+AS13-AS16 -> 9613196.5
C20: 당월 신규 발주 공급가 | D20: 원 | F20: =SUM(J20:U20) -> 40500000 | G20: =SUM(V20:AG20) -> 57000000 | H20: =SUM(AH20:AS20) -> 72000000 | J20: =IF(J$6+'01_가정'!$F$101<=36,INDEX($J$13:$AS$13,1,MIN(36,J$6+'01_가정'!$F$101)),0)+IF('01_가정'!$F$101>0,SUM($J$13:INDEX($J$13:$AS$13,1,MAX(1,MIN(36,'01_가정'!$F$101)))),0) -> 0 | K20: =IF(K$6+'01_가정'!$F$101<=36,INDEX($J$13:$AS$13,1,MIN(36,K$6+'01_가정'!$F$101)),0) -> 0 | L20: =IF(L$6+'01_가정'!$F$101<=36,INDEX($J$13:$AS$13,1,MIN(36,L$6+'01_가정'!$F$101)),0) -> 0 | M20: =IF(M$6+'01_가정'!$F$101<=36,INDEX($J$13:$AS$13,1,MIN(36,M$6+'01_가정'!$F$101)),0) -> 0 | N20: =IF(N$6+'01_가정'!$F$101<=36,INDEX($J$13:$AS$13,1,MIN(36,N$6+'01_가정'!$F$101)),0) -> 0 | O20: =IF(O$6+'01_가정'!$F$101<=36,INDEX($J$13:$AS$13,1,MIN(36,O$6+'01_가정'!$F$101)),0) -> 0 | P20: =IF(P$6+'01_가정'!$F$101<=36,INDEX($J$13:$AS$13,1,MIN(36,P$6+'01_가정'!$F$101)),0) -> 0 | Q20: =IF(Q$6+'01_가정'!$F$101<=36,INDEX($J$13:$AS$13,1,MIN(36,Q$6+'01_가정'!$F$101)),0) -> 21000000 | R20: =IF(R$6+'01_가정'!$F$101<=36,INDEX($J$13:$AS$13,1,MIN(36,R$6+'01_가정'!$F$101)),0) -> 0 | ... AS20: =IF(AS$6+'01_가정'!$F$101<=36,INDEX($J$13:$AS$13,1,MIN(36,AS$6+'01_가정'!$F$101)),0) -> 0
C21: 제조 선금 지급 VAT 포함 | D21: 원 | F21: =SUM(J21:U21) -> 22275000 | G21: =SUM(V21:AG21) -> 31350000 | H21: =SUM(AH21:AS21) -> 39600000 | J21: =J20*'01_가정'!$F$102*(1+'01_가정'!$F$85) -> 0 | K21: =K20*'01_가정'!$F$102*(1+'01_가정'!$F$85) -> 0 | L21: =L20*'01_가정'!$F$102*(1+'01_가정'!$F$85) -> 0 | M21: =M20*'01_가정'!$F$102*(1+'01_가정'!$F$85) -> 0 | N21: =N20*'01_가정'!$F$102*(1+'01_가정'!$F$85) -> 0 | O21: =O20*'01_가정'!$F$102*(1+'01_가정'!$F$85) -> 0 | P21: =P20*'01_가정'!$F$102*(1+'01_가정'!$F$85) -> 0 | Q21: =Q20*'01_가정'!$F$102*(1+'01_가정'!$F$85) -> 11550000 | ... AS21: =AS20*'01_가정'!$F$102*(1+'01_가정'!$F$85) -> 0
